Workbook

Sheet 00_LEIA-ME
B2: APP — Agro Peças Padrão | Master de Produtos Shopify
B3: Documento de referência única (single source of truth) para subida e atualização de produtos.
B5: 📋 OBJETIVO
B6: Padronizar o cadastro de produtos antes de subir para o Shopify (via CSV import, Admin API ou Shopify CLI/MCP). Esta planilha consolida custo, frete inbound, embalagem (peso+dimensões), margem, taxa Mercado Pago e pesquisa de mercado por SKU — eliminando re-trabalho e divergência entre planilha e loja.
B8: 🗂️ ESTRUTURA DAS ABAS
B9: • 00_LEIA-ME — este guia • 01_CONFIG_GLOBAL — parâmetros globais (taxa MP, margem padrão, frete padrão) usados como referência em todas as abas • 02_SOHIPREN — bombas hidráulicas (1.005 SKUs já pré-carregados) • 03_AGRAL — peças plásticas injetadas (35 SKUs pré-carregados) • 04_GRECO — sensores agrícolas (11 SKUs pré-carregados) • 05_AGCO — peças plásticas (22 SKUs pré-carregados) • 06_ADG — estrutura vazia (aguardando definição da parceria) • 08_RESUMO_GERAL — dashboard de status • 09_PESQUISA_MERCADO — consolidação dos preços de concorrência
B11: 🎨 CONVENÇÃO DE CORES
B12: • Verde Campo (#1B4332) — cabeçalhos primários • Dourado (#D4AF37) — agrupamentos • Texto azul — célula de INPUT do operador • Fundo cinza claro — célula CALCULADA (não editar) • Fundo amarelo — FALTA dado, pesquisar / preencher • Fundo verde claro — Posicionamento abaixo da concorrência (oportunidade) • Fundo vermelho claro — Posicionamento acima ou cadastro divergente
B14: 🔑 CHAVE DE MATCH COM SHOPIFY
B15: A coluna 'SKU / Código' (coluna A) é a chave única que liga esta planilha ao Shopify. • SOHIPREN → coluna 'Codigo' da MACRO (ex: 5.1621.0620002.0) • AGRAL → coluna 'Referencia' da MACRO (ex: 6424-4005) • GRECO → coluna 'Código' da MACRO (ex: GR141207) • AGCO → coluna 'Código' da MACRO (ex: ACX3266690) Todos esses códigos devem ser gravados no campo 'SKU' do variant do Shopify.
B17: ⚙️ FÓRMULAS AUTOMÁTICAS
B18: • Handle (Shopify) — slug gerado do Title • Peso cubado (kg) = (C × L × A em cm) / 6000 • Peso considerado = MAX(peso real, peso cubado) — é o que a transportadora cobra • Custo + frete inbound = Custo unitário + Frete fábrica→eCom • Preço c/ margem = (Custo+frete) / (1 − %margem) • Taxa MP () = Preço c/ margem × Taxa MP global • Preço final site = Preço c/ margem / (1 − Taxa MP) • Posicionamento = compara preço final vs média concorrência
... B1006: Dashboard executivo de integrações: acompanhe fotos, descrições e divergências (link enviado à parte).

Sheet 01_CONFIG_GLOBAL
B1: Parâmetros Globais — APP
B2: Parâmetro | C2: Valor | D2: Observação
B3: Margem padrão (referência) | C3: 0.3 | D3: Usada como sugestão inicial — cada SKU pode ter sua margem
B4: Taxa Mercado Pago (%) | C4: 0.05 | D4: Cartão à vista padrão (4,99%) — ajustar se mudar de plano
B5: Taxa MP (parcelado 12x s/ juros) | C5: 0.1682 | D5: Referência para análise — não aplicada automaticamente
B6: Frete inbound padrão () | C6: 25 | D6: Estimativa default por volume — substituir por valor real
B7: ICMS-ST aplicável | C7: verificar | D7: Conforme NCM/CFOP da peça — consultar contador
B8: IPI aplicável | C8: verificar | D8: Conforme classificação fiscal
B9: Markup mínimo aceitável (%) | C9: 0.25 | D9: Threshold para alerta — abaixo disso, revisar
B10: ROAS mínimo Google Ads | C10: 4 | D10: Meta para campanhas pagas — abaixo disso, pausar criativo
B11: Frete grátis (acima de ) | C11: 800 | D11: Política comercial — ajustar conforme caixa
B12: CNPJ APP | D12: Razão social: Agro Peças Padrão
B13: WhatsApp comercial | C13: +55 41 98415-1085 | D13: CTA padrão de todos os produtos
B14: Taxa MP efetiva (5% cartão + parcelado 12x 16,82%) | C14: 0.2082 | D14: FONTE ÚNICA da taxa usada no Preço final de TODAS as abas. Decisão 21/07/2026.
B16: Glossario
B17: Campo | C17: Exemplo | D17: Descrição
A18: IDENTIFICAÇÃO | B18: SKU / Código | C18: 5.1302.0565122.0 | D18: Codigo ou SKU da Peça ideal q seja igual de fabrica para ajudar a "Linkar" na nota
B19: Part Number | C19: 565122 | D19: Part Number ou OEM da Peça isso ajuda na aplicacao da peça
B20: Handle (Shopify) | C20: =IFERROR(LOWER(SUBSTITUTE(SUBSTITUTE(SUBSTITUTE(SUBSTITUTE(C21," ","-"),"/","-"),".",""),",","")),"") | D20: Se não souber preencher o Robozinho preenche para subir para o Ecommerce
B21: Title (PT-BR) | C21: BOMBA HIDRÁULICA - APLICAÇÃO MF A-028 (ACX5148180) GIRO I (PROTOTIPO) | D21: Titulo descritivo ideal para ir ao ecomerce (usar catalo ou pesquisa para ter uma melhor nome )
B22: Product Type | C22: Bombas Hidráulicas | D22: Tipo/Categora de produto veriricar os tipos que hoje temos cadastradas no site antes de criar se criar informar para replicar nos sistemas
B23: Vendor (Fabricante) | C23: SOHIPREN | D23: Fabricante
B24: Tags (vírgula) | D24: Indicadores que ajuda na BUSCA ou pesquisa (Ex: "Produto novo 2026", "Promoçao de Natal","Negociacao Fabio")
B25: Status | C25: active | D25: "activo" para subir ao ecommerce -"Draft" Somente castro na planilha não sobe - "Archived" Produdo não vendido mais no ecom (histórico)
A26: APLICAÇÃO TÉCNICA | B26: Montadora compatível | C26: AGCO | D26: Montadora compativo (ex: AGCO, JOHN DEERE, VOLO ) add todoas as marcas separadas por ","
B27: Equipamento / Modelo | C27: TRATOR | D27: Modelo específico do equipamento onde a peça é aplicada (ex: TRATOR, COLHEITADEIRA, CBT 2500 — quanto mais específico melhor para o cliente encontrar)
B28: Função / Aplicação | C28: PRINCIPAL E DIREÇÃO | D28: Sistema ou função que a peça exerce no equipamento (ex: DIREÇÃO, LEVANTE, PRINCIPAL — baseado no catálogo do fabricante)
B29: Códigos cruzados | C29: R979107777/ACW4000800/ACX5148180 | D29: Outros códigos OEM ou referências cruzadas que identificam a mesma peça em outros fabricantes/montadoras — separar por "/" (ex: R979107777/ACW4000800)
A30: LOGÍSTICA E EMBALAGEM | B30: Peso (kg) | C30: 5.75 | D30: Peso bruto real da peça em kg — pesar fisicamente ou consultar fornecedor. Essencial para calcular frete
B31: Comprimento (cm) | C31: 30 | D31: Comprimento (cm) → Maior dimensão da embalagem em centímetros
B32: Largura (cm) | C32: 12.5 | D32: Largura (cm) → Segunda dimensão da embalagem em centímetros
B33: Altura (cm) | C33: 12.5 | D33: Altura (cm) → Terceira dimensão (espessura) da embalagem em centímetros
B34: Peso cubado (kg) | C34: =IFERROR(IF(AND(C31>0,C32>0,C33>0),(C31*C32*C33)/6000,""),"") | D34: Calculado automaticamente: (C × L × A em cm) ÷ 6.000 — fórmula padrão das transportadoras
B35: Peso considerado (kg) | C35: =IFERROR(IF(AND(C30>0,C34>0),MAX(C30,C34),IF(C30>0,C30,IF(C34>0,C34,""))),"") | D35: Calculado automaticamente: MAX(peso real, peso cubado) — é o valor que a transportadora efetivamente cobra
B36: Frete fábrica → eCom () | C36: 100 | D36: Custo de frete do fabricante até o nosso estoque (inbound). Usar 25,00 como estimativa padrão quando não tiver o valor real
B37: Origem do dado embalagem | C37: fornecedor | D37: Indica de onde vieram as dimensões/peso: "fornecedor" = dado oficial, "FALTA" = pendente de preenchimento, "estimado" = valor aproximado por família de produto
A38: CUSTO E PRECIFICAÇÃO | B38: Custo unitário () | C38: 1290 | D38: Preço de compra da peça junto ao fornecedor (sem frete). Base de todo o cálculo de precificação
B39: % Margem de lucro | C39: 0.3 | D39: Percentual de margem desejado para este SKU. Padrão global: 30% — pode ser ajustado por produto conforme concorrência
B40: Custo + frete inbound () | C40: =IFERROR(C38+C36,"") | D40: Calculado: Custo unitário + Frete fábrica → eCom. Representa o custo total de aquisição da peça no estoque
B41: Preço c/ margem () | C41: =IFERROR(IF(C39<1,C40/(1-C39),""),"") | D41: Calculado: (Custo + frete) ÷ (1 − % margem). Preço mínimo antes de aplicar taxa do Mercado Pago
...

Sheet 02_SOHIPREN
A1: APP — Agro Peças Padrão | Master 02_SOHIPREN
A2: Total de SKUs: | B2: =COUNTA(A6:A100002) | D2: Faltando embalagem: | E2: =COUNTIF(U6:U100002,"FALTA") | G2: Cadastrados Shopify: | H2: =COUNTIF(AK6:AK100002,"sim") | J2: Divergentes: | K2: =COUNTIF(AK6:AK100002,"divergente")
A4: IDENTIFICAÇÃO | I4: APLICAÇÃO TÉCNICA | N4: LOGÍSTICA E EMBALAGEM | V4: CUSTO E PRECIFICAÇÃO | AC4: PESQUISA DE MERCADO | AK4: WORKFLOW | AO4: Campos Adicionais
A5: SKU / Código | B5: Part Number | C5: Handle (Shopify) | D5: Title (PT-BR) | E5: Product Type | F5: Vendor (Fabricante) | G5: Tags (vírgula) | H5: Status | I5: Montadora compatível | J5: Equipamento / Modelo | K5: Função / Aplicação | L5: Códigos cruzados | M5: Lead Time | N5: Peso (kg) | O5: Comprimento (cm) | P5: Largura (cm) | Q5: Altura (cm) | R5: Peso cubado (kg) | S5: Peso considerado (kg) | T5: Frete fábrica → eCom () | U5: Origem do dado embalagem | V5: Custo unitário () | W5: % Margem de lucro | X5: Custo + frete inbound () | Y5: Preço c/ margem () | Z5: Taxa Mercado Pago (%) | AA5: Taxa MP () | AB5: Preço final site () | AC5: Concorrente 1 — Nome | AD5: Concorrente 1 — Preço () | AE5: Concorrente 2 — Nome | AF5: Concorrente 2 — Preço () | AG5: Concorrente 3 — Nome | AH5: Concorrente 3 — Preço () | AI5: Preço médio concorrência () | AJ5: Posicionamento | AK5: Cadastrado Shopify? | AL5: Última atualização | AM5: Operador responsável | AN5: Observações | AO5: SKU Shopify (derivado) | AP5: Título Shopify (derivado) | AQ5: Imagens site (assets)
A6: 5.0202.0540008.0 | B6: 540008 | C6: =IFERROR(LOWER(SUBSTITUTE(SUBSTITUTE(SUBSTITUTE(SUBSTITUTE(D6," ","-"),"/","-"),".",""),",","")),"") | D6: BOMBA HIDRÁULICA - APLICAÇÃO 4 B1.P1.A.L | E6: Bombas Hidráulicas | F6: SOHIPREN | H6: draft | I6: BERTHOUD | J6: CANHÇAO DE PULVERIZAÇÃO | K6: PRINCIPAL | R6: =IFERROR(IF(AND(O6>0,P6>0,Q6>0),(O6*P6*Q6)/6000,""),"") | S6: =IFERROR(IF(AND(N6>0,R6>0),MAX(N6,R6),IF(N6>0,N6,IF(R6>0,R6,""))),"") | U6: FALTA | V6: 517 | W6: 0.3 | X6: =IFERROR(V6+T6,"") | Y6: =IFERROR(IF(W6<1,X6/(1-W6),""),"") | Z6: ='01_CONFIG_GLOBAL'!$C$14 | AA6: =IFERROR(Y6*Z6,"") | AB6: =IFERROR(IF(Z6<1,Y6/(1-Z6),""),"") | AI6: =IFERROR(AVERAGE(AD6,AF6,AH6),"") | AJ6: =IFERROR(IF(AI6="","sem dados",IF(AB6<AI6*0.95,"abaixo",IF(AB6>AI6*1.05,"acima","em linha"))),"") | AK6: não | AO6: =A6 | AP6: =D6
A7: 5.1621.0620002.0 | C7: =IFERROR(LOWER(SUBSTITUTE(SUBSTITUTE(SUBSTITUTE(SUBSTITUTE(D7," ","-"),"/","-"),".",""),",","")),"") | D7: BPBS2-100-A12-Y4 | F7: SOHIPREN | H7: draft | I7: CBT - COMPANHIA BRASILEIRA DE TRATORES | J7: TRATOR | K7: HIDROSTÁTICO | L7: 2100802053 | R7: =IFERROR(IF(AND(O7>0,P7>0,Q7>0),(O7*P7*Q7)/6000,""),"") | S7: =IFERROR(IF(AND(N7>0,R7>0),MAX(N7,R7),IF(N7>0,N7,IF(R7>0,R7,""))),"") | U7: FALTA | V7: 826.55 | W7: 0.3 | X7: =IFERROR(V7+T7,"") | Y7: =IFERROR(IF(W7<1,X7/(1-W7),""),"") | Z7: ='01_CONFIG_GLOBAL'!$C$14 | AA7: =IFERROR(Y7*Z7,"") | AB7: =IFERROR(IF(Z7<1,Y7/(1-Z7),""),"") | AI7: =IFERROR(AVERAGE(AD7,AF7,AH7),"") | AJ7: =IFERROR(IF(AI7="","sem dados",IF(AB7<AI7*0.95,"abaixo",IF(AB7>AI7*1.05,"acima","em linha"))),"") | AK7: não | AO7: =A7 | AP7: =D7
A8: 5.0207.0544003.0 | B8: 544003 | C8: =IFERROR(LOWER(SUBSTITUTE(SUBSTITUTE(SUBSTITUTE(SUBSTITUTE(D8," ","-"),"/","-"),".",""),",","")),"") | D8: BOMBA HIDRÁULICA - APLICAÇÃO 14 C5.C4.B1.C5 12-100 BAR | E8: Bombas Hidráulicas | F8: SOHIPREN | H8: draft | I8: CBT - COMPANHIA BRASILEIRA DE TRATORES | J8: CBT 2500 - 8260 PERKINS - ZF | K8: DIREÇÃO | L8: 7673955928 | R8: =IFERROR(IF(AND(O8>0,P8>0,Q8>0),(O8*P8*Q8)/6000,""),"") | S8: =IFERROR(IF(AND(N8>0,R8>0),MAX(N8,R8),IF(N8>0,N8,IF(R8>0,R8,""))),"") | U8: FALTA | V8: 427.9 | W8: 0.3 | X8: =IFERROR(V8+T8,"") | Y8: =IFERROR(IF(W8<1,X8/(1-W8),""),"") | Z8: ='01_CONFIG_GLOBAL'!$C$14 | AA8: =IFERROR(Y8*Z8,"") | AB8: =IFERROR(IF(Z8<1,Y8/(1-Z8),""),"") | AI8: =IFERROR(AVERAGE(AD8,AF8,AH8),"") | AJ8: =IFERROR(IF(AI8="","sem dados",IF(AB8<AI8*0.95,"abaixo",IF(AB8>AI8*1.05,"acima","em linha"))),"") | AK8: não | AO8: =A8 | AP8: =D8
A9: 5.0207.0544001.0 | B9: 544001 | C9: =IFERROR(LOWER(SUBSTITUTE(SUBSTITUTE(SUBSTITUTE(SUBSTITUTE(D9," ","-"),"/","-"),".",""),",","")),"") | D9: BOD 14 C5.C4.B1.C5 12-100 BAR | E9: Bombas Hidráulicas | F9: SOHIPREN | H9: draft | I9: CBT - COMPANHIA BRASILEIRA DE TRATORES | J9: CBT 2500 - 8260 MERCEDEZ -ZF | K9: DIREÇÃO | L9: 7673955928 | R9: =IFERROR(IF(AND(O9>0,P9>0,Q9>0),(O9*P9*Q9)/6000,""),"") | S9: =IFERROR(IF(AND(N9>0,R9>0),MAX(N9,R9),IF(N9>0,N9,IF(R9>0,R9,""))),"") | U9: FALTA | V9: 665 | W9: 0.3 | X9: =IFERROR(V9+T9,"") | Y9: =IFERROR(IF(W9<1,X9/(1-W9),""),"") | Z9: ='01_CONFIG_GLOBAL'!$C$14 | AA9: =IFERROR(Y9*Z9,"") | AB9: =IFERROR(IF(Z9<1,Y9/(1-Z9),""),"") | AI9: =IFERROR(AVERAGE(AD9,AF9,AH9),"") | AJ9: =IFERROR(IF(AI9="","sem dados",IF(AB9<AI9*0.95,"abaixo",IF(AB9>AI9*1.05,"acima","em linha"))),"") | AK9: não | AO9: =A9 | AP9: =D9
A10: 5.0208.0544811.0 | B10: 544811 | C10: =IFERROR(LOWER(SUBSTITUTE(SUBSTITUTE(SUBSTITUTE(SUBSTITUTE(D10," ","-"),"/","-"),".",""),",","")),"") | D10: BOMBA HIDRÁULICA - APLICAÇÃO 16 F4.A2.A42.L | E10: Bombas Hidráulicas | F10: SOHIPREN | H10: draft | I10: CBT - COMPANHIA BRASILEIRA DE TRATORES | J10: TRATOR DE PNEUS | K10: LEVANTE 3 PONTO | L10: 103345-90-9510080608-99061002-90611257-11111016014 | R10: =IFERROR(IF(AND(O10>0,P10>0,Q10>0),(O10*P10*Q10)/6000,""),"") | S10: =IFERROR(IF(AND(N10>0,R10>0),MAX(N10,R10),IF(N10>0,N10,IF(R10>0,R10,""))),"") | U10: FALTA | V10: 786.5 | W10: 0.3 | X10: =IFERROR(V10+T10,"") | Y10: =IFERROR(IF(W10<1,X10/(1-W10),""),"") | Z10: ='01_CONFIG_GLOBAL'!$C$14 | AA10: =IFERROR(Y10*Z10,"") | AB10: =IFERROR(IF(Z10<1,Y10/(1-Z10),""),"") | AI10: =IFERROR(AVERAGE(AD10,AF10,AH10),"") | AJ10: =IFERROR(IF(AI10="","sem dados",IF(AB10<AI10*0.95,"abaixo",IF(AB10>AI10*1.05,"acima","em linha"))),"") | AK10: não | AO10: =A10 | AP10: =D10
A11: 5.0205.0542421.0 | B11: 542421 | C11: =IFERROR(LOWER(SUBSTITUTE(SUBSTITUTE(SUBSTITUTE(SUBSTITUTE(D11," ","-"),"/","-"),".",""),",","")),"") | D11: BOD 8 F4.A2.A.L | E11: Bombas Hidráulicas | F11: SOHIPREN | H11: draft | I11: DYNAPAC | J11: COMPACTADOR | K11: DIREÇÃO | L11: 300480606-9510080403-11101008011-9906003-41082905 | R11: =IFERROR(IF(AND(O11>0,P11>0,Q11>0),(O11*P11*Q11)/6000,""),"") | S11: =IFERROR(IF(AND(N11>0,R11>0),MAX(N11,R11),IF(N11>0,N11,IF(R11>0,R11,""))),"") | U11: FALTA | V11: 605 | W11: 0.3 | X11: =IFERROR(V11+T11,"") | Y11: =IFERROR(IF(W11<1,X11/(1-W11),""),"") | Z11: ='01_CONFIG_GLOBAL'!$C$14 | AA11: =IFERROR(Y11*Z11,"") | AB11: =IFERROR(IF(Z11<1,Y11/(1-Z11),""),"") | AI11: =IFERROR(AVERAGE(AD11,AF11,AH11),"") | AJ11: =IFERROR(IF(AI11="","sem dados",IF(AB11<AI11*0.95,"abaixo",IF(AB11>AI11*1.05,"acima","em linha"))),"") | AK11: não | AO11: =A11 | AP11: =D11
A12: 5.0906.0580532.0 | B12: 580532 | C12: =IFERROR(LOWER(SUBSTITUTE(SUBSTITUTE(SUBSTITUTE(SUBSTITUTE(D12," ","-"),"/","-"),".",""),",","")),"") | D12: APR 50 201.1.37.83 | F12: SOHIPREN | H12: draft | I12: FORD | J12: PÁ COM RETRO ESCAVADEIRA | | K12: PRINCIPAL | L12: VB-300 | R12: =IFERROR(IF(AND(O12>0,P12>0,Q12>0),(O12*P12*Q12)/6000,""),"") | S12: =IFERROR(IF(AND(N12>0,R12>0),MAX(N12,R12),IF(N12>0,N12,IF(R12>0,R12,""))),"") | U12: FALTA | V12: 1018.22 | W12: 0.3 | X12: =IFERROR(V12+T12,"") | Y12: =IFERROR(IF(W12<1,X12/(1-W12),""),"") | Z12: ='01_CONFIG_GLOBAL'!$C$14 | AA12: =IFERROR(Y12*Z12,"") | AB12: =IFERROR(IF(Z12<1,Y12/(1-Z12),""),"") | AI12: =IFERROR(AVERAGE(AD12,AF12,AH12),"") | AJ12: =IFERROR(IF(AI12="","sem dados",IF(AB12<AI12*0.95,"abaixo",IF(AB12>AI12*1.05,"acima","em linha"))),"") | AK12: não | AO12: =A12 | AP12: =D12
A13: 5.1621.0680005.0 | B13: 680005 | C13: =IFERROR(LOWER(SUBSTITUTE(SUBSTITUTE(SUBSTITUTE(SUBSTITUTE(D13," ","-"),"/","-"),".",""),",","")),"") | D13: Motor Hidráulico MLR 160 - Plantadeira AGCO (C3.C2.P5) | E13: MOTOR | F13: SOHIPREN | H13: active | I13: AGCO | J13: PLANTANDEIRA | L13: ACX3995300 | N13: 6.2 | O13: 30 | P13: 12.5 | Q13: 12.5 | R13: =IFERROR(IF(AND(O13>0,P13>0,Q13>0),(O13*P13*Q13)/6000,""),"") | S13: =IFERROR(IF(AND(N13>0,R13>0),MAX(N13,R13),IF(N13>0,N13,IF(R13>0,R13,""))),"") | T13: 100 | U13: fornecedor | V13: 767.55 | W13: 0.2 | X13: =IFERROR(V13+T13,"") | Y13: =IFERROR(IF(W13<1,X13/(1-W13),""),"") | Z13: ='01_CONFIG_GLOBAL'!$C$14 | AA13: =IFERROR(Y13*Z13,"") | AB13: =IFERROR(IF(Z13<1,Y13/(1-Z13),""),"") | AI13: =IFERROR(AVERAGE(AD13,AF13,AH13),"") | AJ13: =IFERROR(IF(AI13="","sem dados",IF(AB13<AI13*0.95,"abaixo",IF(AB13>AI13*1.05,"acima","em linha"))),"") | AK13: sim | AO13: =A13 | AP13: =D13 | AQ13: SEM IMAGEM
A14: 5.1302.0565122.0 | B14: 565122 | C14: =IFERROR(LOWER(SUBSTITUTE(SUBSTITUTE(SUBSTITUTE(SUBSTITUTE(D14," ","-"),"/","-"),".",""),",","")),"") | D14: Bomba de Aplicação Massey Ferguson A-028 (ACX5148180) Giro I - 5.1302.0565122.0 | E14: Bombas Hidráulicas | F14: SOHIPREN | H14: active | I14: AGCO | J14: TRATOR | K14: PRINCIPAL E DIREÇÃO | L14: R979107777/ACW4000800/ACX5148180 | N14: 5.75 | O14: 30 | P14: 12.5 | Q14: 12.5 | R14: =IFERROR(IF(AND(O14>0,P14>0,Q14>0),(O14*P14*Q14)/6000,""),"") | S14: =IFERROR(IF(AND(N14>0,R14>0),MAX(N14,R14),IF(N14>0,N14,IF(R14>0,R14,""))),"") | T14: 100 | U14: fornecedor | V14: 1096.5 | W14: 0.2 | X14: =IFERROR(V14+T14,"") | Y14: =IFERROR(IF(W14<1,X14/(1-W14),""),"") | Z14: ='01_CONFIG_GLOBAL'!$C$14 | AA14: =IFERROR(Y14*Z14,"") | AB14: =IFERROR(IF(Z14<1,Y14/(1-Z14),""),"") | AI14: =IFERROR(AVERAGE(AD14,AF14,AH14),"") | AJ14: =IFERROR(IF(AI14="","sem dados",IF(AB14<AI14*0.95,"abaixo",IF(AB14>AI14*1.05,"acima","em linha"))),"") | AK14: sim | AO14: =A14 | AP14: =D14 | AQ14: bomba_generica.png (genérica)
A15: 5.1302.0565120.0 | B15: 565120 | C15: =IFERROR(LOWER(SUBSTITUTE(SUBSTITUTE(SUBSTITUTE(SUBSTITUTE(D15," ","-"),"/","-"),".",""),",","")),"") | D15: Motor de Aplicação Massey Ferguson A-026 (ACX4630870) Giro D - 5.1302.0565120.0 | E15: MOTOR | F15: SOHIPREN | H15: active | I15: AGCO | J15: PLANTADEIRA | K15: MOTOR DA TURNINA | L15: ACX4630870 SUBISTITUI ACW9357690 | N15: 5.98 | O15: 30 | P15: 12.5 | Q15: 12.5 | R15: =IFERROR(IF(AND(O15>0,P15>0,Q15>0),(O15*P15*Q15)/6000,""),"") | S15: =IFERROR(IF(AND(N15>0,R15>0),MAX(N15,R15),IF(N15>0,N15,IF(R15>0,R15,""))),"") | T15: 100 | U15: fornecedor | V15: 1147.5 | W15: 0.2 | X15: =IFERROR(V15+T15,"") | Y15: =IFERROR(IF(W15<1,X15/(1-W15),""),"") | Z15: ='01_CONFIG_GLOBAL'!$C$14 | AA15: =IFERROR(Y15*Z15,"") | AB15: =IFERROR(IF(Z15<1,Y15/(1-Z15),""),"") | AI15: =IFERROR(AVERAGE(AD15,AF15,AH15),"") | AJ15: =IFERROR(IF(AI15="","sem dados",IF(AB15<AI15*0.95,"abaixo",IF(AB15>AI15*1.05,"acima","em linha"))),"") | AK15: sim | AO15: =A15 | AP15: =D15 | AQ15: SEM IMAGEM
A16: 5.0208.L025883.0 | B16: L025883 | C16: =IFERROR(LOWER(SUBSTITUTE(SUBSTITUTE(SUBSTITUTE(SUBSTITUTE(D16," ","-"),"/","-"),".",""),",","")),"") | D16: BOMBA HIDRÁULICA - APLICAÇÃO 16 E18.C.A.L | E16: Bombas Hidráulicas | F16: SOHIPREN | H16: draft | I16: AGCO | J16: TRATOR | L16: 86664800/0510625329 | R16: =IFERROR(IF(AND(O16>0,P16>0,Q16>0),(O16*P16*Q16)/6000,""),"") | S16: =IFERROR(IF(AND(N16>0,R16>0),MAX(N16,R16),IF(N16>0,N16,IF(R16>0,R16,""))),"") | U16: FALTA | V16: 665 | W16: 0.3 | X16: =IFERROR(V16+T16,"") | Y16: =IFERROR(IF(W16<1,X16/(1-W16),""),"") | Z16: ='01_CONFIG_GLOBAL'!$C$14 | AA16: =IFERROR(Y16*Z16,"") | AB16: =IFERROR(IF(Z16<1,Y16/(1-Z16),""),"") | AI16: =IFERROR(AVERAGE(AD16,AF16,AH16),"") | AJ16: =IFERROR(IF(AI16="","sem dados",IF(AB16<AI16*0.95,"abaixo",IF(AB16>AI16*1.05,"acima","em linha"))),"") | AK16: não | AO16: =A16 | AP16: =D16
A17: 5.0220.0548836.0 | B17: 548836 | C17: =IFERROR(LOWER(SUBSTITUTE(SUBSTITUTE(SUBSTITUTE(SUBSTITUTE(D17," ","-"),"/","-"),".",""),",","")),"") | D17: Bomba de Direção Massey Ferguson 194-4F/362/365/372/390 | E17: Bombas Hidráulicas | F17: SOHIPREN | H17: active | I17: AGCO - MASSEY FERGUNSON | J17: TRATOR | K17: DIREÇÃO E AUXILIAR | L17: 3774612/3701005/6214827/3597692/3595202/3597706/F800510536 - 42603990020 | N17: 5.33 | O17: 30 | P17: 12.5 | Q17: 12.5 | R17: =IFERROR(IF(AND(O17>0,P17>0,Q17>0),(O17*P17*Q17)/6000,""),"") | S17: =IFERROR(IF(AND(N17>0,R17>0),MAX(N17,R17),IF(N17>0,N17,IF(R17>0,R17,""))),"") | T17: 100 | U17: fornecedor | V17: 1207 | W17: 0.2 | X17: =IFERROR(V17+T17,"") | Y17: =IFERROR(IF(W17<1,X17/(1-W17),""),"") | Z17: ='01_CONFIG_GLOBAL'!$C$14 | AA17: =IFERROR(Y17*Z17,"") | AB17: =IFERROR(IF(Z17<1,Y17/(1-Z17),""),"") | AI17: =IFERROR(AVERAGE(AD17,AF17,AH17),"") | AJ17: =IFERROR(IF(AI17="","sem dados",IF(AB17<AI17*0.95,"abaixo",IF(AB17>AI17*1.05,"acima","em linha"))),"") | AK17: sim | AN17: Fotos: assets/livenza_5.0220.0548836-CT_REV._0_p1.png | AO17: =A17 | AP17: =D17 | AQ17: 0012_548836_Livenza_5_0220_0548836-CT_0_att101_p1_foto_3d_ecommerce.png | 0012_548836_Livenza_5_0220_0548836-CT_0_att101_p1_desenho_tec.png | livenza_5.0220.0548836-CT_REV._0_p1.png
A18: 5.0220.0548817.0 | B18: 548817 | C18: =IFERROR(LOWER(SUBSTITUTE(SUBSTITUTE(SUBSTITUTE(SUBSTITUTE(D18," ","-"),"/","-"),".",""),",","")),"") | D18: Bomba Hidráulica Massey Ferguson 283/290/292/L5000 - Direção e Levante | E18: Bombas Hidráulicas | F18: SOHIPREN | H18: active | I18: AGCO - MASSEY FERGUNSON | J18: TRATOR | K18: DIREÇÃO E LEVANTE | L18: 052107T1 | N18: 5.69 | O18: 30 | P18: 12.5 | Q18: 12.5 | R18: =IFERROR(IF(AND(O18>0,P18>0,Q18>0),(O18*P18*Q18)/6000,""),"") | S18: =IFERROR(IF(AND(N18>0,R18>0),MAX(N18,R18),IF(N18>0,N18,IF(R18>0,R18,""))),"") | T18: 100 | U18: fornecedor | V18: 913.75 | W18: 0.2 | X18: =IFERROR(V18+T18,"") | Y18: =IFERROR(IF(W18<1,X18/(1-W18),""),"") | Z18: ='01_CONFIG_GLOBAL'!$C$14 | AA18: =IFERROR(Y18*Z18,"") | AB18: =IFERROR(IF(Z18<1,Y18/(1-Z18),""),"") | AI18: =IFERROR(AVERAGE(AD18,AF18,AH18),"") | AJ18: =IFERROR(IF(AI18="","sem dados",IF(AB18<AI18*0.95,"abaixo",IF(AB18>AI18*1.05,"acima","em linha"))),"") | AK18: sim | AO18: =A18 | AP18: =D18 | AQ18: LIVENZA_5.0220.0548817_ecommerce.jpg
A19: 5.1302.0565053.0 | B19: 565053 | C19: =IFERROR(LOWER(SUBSTITUTE(SUBSTITUTE(SUBSTITUTE(SUBSTITUTE(D19," ","-"),"/","-"),".",""),",","")),"") | D19: Bomba Hidráulica Massey Ferguson MF A-016 - Trator 4299 | E19: Bombas Hidráulicas | F19: SOHIPREN | H19: active | I19: AGCO - MASSEY FERGUNSON | J19: TRATOR DE PNEUS | K19: PRINCIPAL - 22,5+11 | L19: 6262009 - R979017550 - 11112022040 - 9033102550 | N19: 9.33 | O19: 30 | P19: 12.5 | Q19: 12.5 | R19: =IFERROR(IF(AND(O19>0,P19>0,Q19>0),(O19*P19*Q19)/6000,""),"") | S19: =IFERROR(IF(AND(N19>0,R19>0),MAX(N19,R19),IF(N19>0,N19,IF(R19>0,R19,""))),"") | T19: 100 | U19: fornecedor | V19: 1632 | W19: 0.2 | X19: =IFERROR(V19+T19,"") | Y19: =IFERROR(IF(W19<1,X19/(1-W19),""),"") | Z19: ='01_CONFIG_GLOBAL'!$C$14 | AA19: =IFERROR(Y19*Z19,"") | AB19: =IFERROR(IF(Z19<1,Y19/(1-Z19),""),"") | AI19: =IFERROR(AVERAGE(AD19,AF19,AH19),"") | AJ19: =IFERROR(IF(AI19="","sem dados",IF(AB19<AI19*0.95,"abaixo",IF(AB19>AI19*1.05,"acima","em linha"))),"") | AK19: sim | AN19: Fotos: assets/livenza_5.1302.0565053-1_p1.png | AO19: =A19 | AP19: =D19 | AQ19: 0014_565053_Livenza_5_1302_0565053_att143_p1_foto_3d_ecommerce.png | 0014_565053_Livenza_5_1302_0565053_att143_p1_desenho_tec.png
A20: 5.0239.L012800.0 | B20: L012800 | C20: =IFERROR(LOWER(SUBSTITUTE(SUBSTITUTE(SUBSTITUTE(SUBSTITUTE(D20," ","-"),"/","-"),".",""),",","")),"") | D20: KIT.BO.22,5.E2TD.B20 | F20: SOHIPREN | H20: draft | I20: AGCO - MASSEY FERGUSON | J20: TRATOR | K20: BX200 - 4292 - 4297 - 4299 | L20: R979017553 | R20: =IFERROR(IF(AND(O20>0,P20>0,Q20>0),(O20*P20*Q20)/6000,""),"") | S20: =IFERROR(IF(AND(N20>0,R20>0),MAX(N20,R20),IF(N20>0,N20,IF(R20>0,R20,""))),"") | U20: FALTA | V20: 396 | W20: 0.3 | X20: =IFERROR(V20+T20,"") | Y20: =IFERROR(IF(W20<1,X20/(1-W20),""),"") | Z20: ='01_CONFIG_GLOBAL'!$C$14 | AA20: =IFERROR(Y20*Z20,"") | AB20: =IFERROR(IF(Z20<1,Y20/(1-Z20),""),"") | AI20: =IFERROR(AVERAGE(AD20,AF20,AH20),"") | AJ20: =IFERROR(IF(AI20="","sem dados",IF(AB20<AI20*0.95,"abaixo",IF(AB20>AI20*1.05,"acima","em linha"))),"") | AK20: não | AO20: =A20 | AP20: =D20
A21: 5.0220.0548851.0 | B21: 548851 | C21: =IFERROR(LOWER(SUBSTITUTE(SUBSTITUTE(SUBSTITUTE(SUBSTITUTE(D21," ","-"),"/","-"),".",""),",","")),"") | D21: BOMBA HIDRÁULICA - APLICAÇÃO 16 E5.P.A42/14 A42.L1 (PLACA H15) | E21: Bombas Hidráulicas | F21: SOHIPREN | H21: draft | I21: AGCO - VALTRA | J21: TRATOR | K21: PRINCIPAL | L21: 83410200-9510080642 | R21: =IFERROR(IF(AND(O21>0,P21>0,Q21>0),(O21*P21*Q21)/6000,""),"") | S21: =IFERROR(IF(AND(N21>0,R21>0),MAX(N21,R21),IF(N21>0,N21,IF(R21>0,R21,""))),"") | U21: FALTA | V21: 1317 | W21: 0.3 | X21: =IFERROR(V21+T21,"") | Y21: =IFERROR(IF(W21<1,X21/(1-W21),""),"") | Z21: ='01_CONFIG_GLOBAL'!$C$14 | AA21: =IFERROR(Y21*Z21,"") | AB21: =IFERROR(IF(Z21<1,Y21/(1-Z21),""),"") | AI21: =IFERROR(AVERAGE(AD21,AF21,AH21),"") | AJ21: =IFERROR(IF(AI21="","sem dados",IF(AB21<AI21*0.95,"abaixo",IF(AB21>AI21*1.05,"acima","em linha"))),"") | AK21: não | AO21: =A21 | AP21: =D21
A22: 5.0220.0548824-2 | B22: 548824 | C22: =IFERROR(LOWER(SUBSTITUTE(SUBSTITUTE(SUBSTITUTE(SUBSTITUTE(D22," ","-"),"/","-"),".",""),",","")),"") | D22: Bomba Hidráulica Dupla Valtra-Valmet BH160 | E22: Bombas Hidráulicas | F22: SOHIPREN | H22: active | I22: AGCO - VALTRA | J22: TRATOR | K22: PRINCIPAL | L22: 836659742-836640234-9510080758-R979106433-81341100 | N22: 7.97 | O22: 30 | P22: 12.5 | Q22: 12.5 | R22: =IFERROR(IF(AND(O22>0,P22>0,Q22>0),(O22*P22*Q22)/6000,""),"") | S22: =IFERROR(IF(AND(N22>0,R22>0),MAX(N22,R22),IF(N22>0,N22,IF(R22>0,R22,""))),"") | T22: 100 | U22: fornecedor | V22: 1130.5 | W22: 0.2 | X22: =IFERROR(V22+T22,"") | Y22: =IFERROR(IF(W22<1,X22/(1-W22),""),"") | Z22: ='01_CONFIG_GLOBAL'!$C$14 | AA22: =IFERROR(Y22*Z22,"") | AB22: =IFERROR(IF(Z22<1,Y22/(1-Z22),""),"") | AI22: =IFERROR(AVERAGE(AD22,AF22,AH22),"") | AJ22: =IFERROR(IF(AI22="","sem dados",IF(AB22<AI22*0.95,"abaixo",IF(AB22>AI22*1.05,"acima","em linha"))),"") | AK22: sim | AN22: Fotos: assets/livenza_5.0220.0548824-2_p1.png | AO22: =A22 | AP22: =D22 | AQ22: 0017_548824_Livenza_5_0220_0548951-CT_REV__0_att135_p1_foto_3d_ecommerce.png | 0017_548824_Livenza_5_0220_0548951-CT_REV__0_att135_p1_desenho_tec.png | 5.0220.0548824-2_p1.png
A23: 5.0220.0548917.0 | B23: 548917 | C23: =IFERROR(LOWER(SUBSTITUTE(SUBSTITUTE(SUBSTITUTE(SUBSTITUTE(D23," ","-"),"/","-"),".",""),",","")),"") | D23: Bomba Hidráulica 16 Principal e Direção - Trator Valtra (E2.B8.B2/14, Placa H15) | E23: Bombas Hidráulicas | F23: SOHIPREN | H23: active | I23: AGCO - VALTRA | J23: TRATOR | K23: PRINCIPAL E DIREÇAO | L23: 31851700/9510080542/F000510609 | M23: 10 dias úteis | N23: 7.65 | O23: 30 | P23: 12.5 | Q23: 12.5 | R23: =IFERROR(IF(AND(O23>0,P23>0,Q23>0),(O23*P23*Q23)/6000,""),"") | S23: =IFERROR(IF(AND(N23>0,R23>0),MAX(N23,R23),IF(N23>0,N23,IF(R23>0,R23,""))),"") | T23: 100 | U23: fornecedor | V23: 1130.5 | W23: 0.2 | X23: =IFERROR(V23+T23,"") | Y23: =IFERROR(IF(W23<1,X23/(1-W23),""),"") | Z23: ='01_CONFIG_GLOBAL'!$C$14 | AA23: =IFERROR(Y23*Z23,"") | AB23: =IFERROR(IF(Z23<1,Y23/(1-Z23),""),"") | AI23: =IFERROR(AVERAGE(AD23,AF23,AH23),"") | AJ23: =IFERROR(IF(AI23="","sem dados",IF(AB23<AI23*0.95,"abaixo",IF(AB23>AI23*1.05,"acima","em linha"))),"") | AK23: sim | AO23: =A23 | AP23: =D23 | AQ23: bomba_generica.png (genérica)
A24: 5.0220.L026997.0 | B24: L026997 | C24: =IFERROR(LOWER(SUBSTITUTE(SUBSTITUTE(SUBSTITUTE(SUBSTITUTE(D24," ","-"),"/","-"),".",""),",","")),"") | D24: Bomba Hidráulica 22,5 Principal - Trator Valtra (E2.B8.B112/16.B4/16) | E24: Bombas Hidráulicas | F24: SOHIPREN | H24: active | I24: AGCO - VALTRA | J24: TRATORES | K24: PRINCIPAL | L24: R979003762 - 11113022004 - 84068400 | N24: 9.89 | O24: 35 | P24: 31 | Q24: 20 | R24: =IFERROR(IF(AND(O24>0,P24>0,Q24>0),(O24*P24*Q24)/6000,""),"") | S24: =IFERROR(IF(AND(N24>0,R24>0),MAX(N24,R24),IF(N24>0,N24,IF(R24>0,R24,""))),"") | T24: 100 | U24: fornecedor | V24: 1759.5 | W24: 0.2 | X24: =IFERROR(V24+T24,"") | Y24: =IFERROR(IF(W24<1,X24/(1-W24),""),"") | Z24: ='01_CONFIG_GLOBAL'!$C$14 | AA24: =IFERROR(Y24*Z24,"") | AB24: =IFERROR(IF(Z24<1,Y24/(1-Z24),""),"") | AI24: =IFERROR(AVERAGE(AD24,AF24,AH24),"") | AJ24: =IFERROR(IF(AI24="","sem dados",IF(AB24<AI24*0.95,"abaixo",IF(AB24>AI24*1.05,"acima","em linha"))),"") | AK24: sim | AO24: =A24 | AP24: =D24 | AQ24: bomba_generica.png (genérica)
A25: 5.0220.0547201.0 | B25: 547201 | C25: =IFERROR(LOWER(SUBSTITUTE(SUBSTITUTE(SUBSTITUTE(SUBSTITUTE(D25," ","-"),"/","-"),".",""),",","")),"") | D25: Bomba Hidráulica Principal Valtra-Valmet 885/985/1280 | E25: Bombas Hidráulicas | F25: SOHIPREN | H25: active | I25: AGCO - VALTRA | J25: TRATOR | K25: PRINCIPAL | L25: 81131100/9510080756 | N25: 8.86 | O25: 30 | P25: 12.5 | Q25: 12.5 | R25: =IFERROR(IF(AND(O25>0,P25>0,Q25>0),(O25*P25*Q25)/6000,""),"") | S25: =IFERROR(IF(AND(N25>0,R25>0),MAX(N25,R25),IF(N25>0,N25,IF(R25>0,R25,""))),"") | T25: 100 | U25: fornecedor | V25: 1130.5 | W25: 0.2 | X25: =IFERROR(V25+T25,"") | Y25: =IFERROR(IF(W25<1,X25/(1-W25),""),"") | Z25: ='01_CONFIG_GLOBAL'!$C$14 | AA25: =IFERROR(Y25*Z25,"") | AB25: =IFERROR(IF(Z25<1,Y25/(1-Z25),""),"") | AI25: =IFERROR(AVERAGE(AD25,AF25,AH25),"") | AJ25: =IFERROR(IF(AI25="","sem dados",IF(AB25<AI25*0.95,"abaixo",IF(AB25>AI25*1.05,"acima","em linha"))),"") | AK25: sim | AN25: Fotos: assets/livenza_5.0220.0547201-CT_REV._0_p1.png | AO25: =A25 | AP25: =D25 | AQ25: 0020_547201_Livenza_5_0220_0547201-CT_0_att84_p1_foto_3d_ecommerce.png | 0020_547201_Livenza_5_0220_0547201-CT_0_att84_p1_desenho_tec.png | livenza_5.0220.0547201-CT_REV._0_p1.png
A26: 5.0220.0547202.0 | B26: 547202 | C26: =IFERROR(LOWER(SUBSTITUTE(SUBSTITUTE(SUBSTITUTE(SUBSTITUTE(D26," ","-"),"/","-"),".",""),",","")),"") | D26: Bomba Hidráulica Valtra-Valmet 62/65/68/85/86/88/78EL - Principal | E26: Bombas Hidráulicas | F26: SOHIPREN | H26: active | I26: AGCO - VALTRA | J26: TRATOR DE PNEUS | K26: PRINCIPAL | L26: 159400-1 | M26: 10 dias úteis | N26: 7.98 | O26: 30 | P26: 12.5 | Q26: 12.5 | R26: =IFERROR(IF(AND(O26>0,P26>0,Q26>0),(O26*P26*Q26)/6000,""),"") | S26: =IFERROR(IF(AND(N26>0,R26>0),MAX(N26,R26),IF(N26>0,N26,IF(R26>0,R26,""))),"") | T26: 100 | U26: fornecedor | V26: 1038.7 | W26: 0.2 | X26: =IFERROR(V26+T26,"") | Y26: =IFERROR(IF(W26<1,X26/(1-W26),""),"") | Z26: ='01_CONFIG_GLOBAL'!$C$14 | AA26: =IFERROR(Y26*Z26,"") | AB26: =IFERROR(IF(Z26<1,Y26/(1-Z26),""),"") | AI26: =IFERROR(AVERAGE(AD26,AF26,AH26),"") | AJ26: =IFERROR(IF(AI26="","sem dados",IF(AB26<AI26*0.95,"abaixo",IF(AB26>AI26*1.05,"acima","em linha"))),"") | AK26: sim | AN26: Fotos: assets/livenza_5.0220.0547202-CT_REV._0_p1.png | AO26: =A26 | AP26: =D26 | AQ26: 0021_547202_Livenza_5_0220_0547202-CT_0_att85_p1_foto_3d_ecommerce.png | 0021_547202_Livenza_5_0220_0547202-CT_0_att85_p1_desenho_tec.png
A27: 5.0220.0547791.0 | B27: 547791 | C27: =IFERROR(LOWER(SUBSTITUTE(SUBSTITUTE(SUBSTITUTE(SUBSTITUTE(D27," ","-"),"/","-"),".",""),",","")),"") | D27: BOMBA HIDRÁULICA - APLICAÇÃO 11 E5.P.A42/14 A42.L (CPO DELANTERO - TRASERO INVERTIDO) | E27: Bombas Hidráulicas | F27: SOHIPREN | H27: draft | I27: AGCO - VALTRA | J27: TARTOR | K27: PRINCIPAL E DIREÇÃO | L27: 83431900-9510080542-2122011002 | R27: =IFERROR(IF(AND(O27>0,P27>0,Q27>0),(O27*P27*Q27)/6000,""),"") | S27: =IFERROR(IF(AND(N27>0,R27>0),MAX(N27,R27),IF(N27>0,N27,IF(R27>0,R27,""))),"") | U27: FALTA | V27: 1034 | W27: 0.3 | X27: =IFERROR(V27+T27,"") | Y27: =IFERROR(IF(W27<1,X27/(1-W27),""),"") | Z27: ='01_CONFIG_GLOBAL'!$C$14 | AA27: =IFERROR(Y27*Z27,"") | AB27: =IFERROR(IF(Z27<1,Y27/(1-Z27),""),"") | AI27: =IFERROR(AVERAGE(AD27,AF27,AH27),"") | AJ27: =IFERROR(IF(AI27="","sem dados",IF(AB27<AI27*0.95,"abaixo",IF(AB27>AI27*1.05,"acima","em linha"))),"") | AK27: não | AO27: =A27 | AP27: =D27
A28: 5.0401.0575023.0 | B28: 575023 | C28: =IFERROR(LOWER(SUBSTITUTE(SUBSTITUTE(SUBSTITUTE(SUBSTITUTE(D28," ","-"),"/","-"),".",""),",","")),"") | D28: BND 22 E4.C3.F2.L | F28: SOHIPREN | H28: draft | I28: AGRALE | J28: TRATOR | K28: PRINCIPAL | L28: R979018701/R979018705 | R28: =IFERROR(IF(AND(O28>0,P28>0,Q28>0),(O28*P28*Q28)/6000,""),"") | S28: =IFERROR(IF(AND(N28>0,R28>0),MAX(N28,R28),IF(N28>0,N28,IF(R28>0,R28,""))),"") | U28: FALTA | V28: 665 | W28: 0.3 | X28: =IFERROR(V28+T28,"") | Y28: =IFERROR(IF(W28<1,X28/(1-W28),""),"") | Z28: ='01_CONFIG_GLOBAL'!$C$14 | AA28: =IFERROR(Y28*Z28,"") | AB28: =IFERROR(IF(Z28<1,Y28/(1-Z28),""),"") | AI28: =IFERROR(AVERAGE(AD28,AF28,AH28),"") | AJ28: =IFERROR(IF(AI28="","sem dados",IF(AB28<AI28*0.95,"abaixo",IF(AB28>AI28*1.05,"acima","em linha"))),"") | AK28: não | AO28: =A28 | AP28: =D28
A29: 5.0208.L025260.0 | B29: L02526 | C29: =IFERROR(LOWER(SUBSTITUTE(SUBSTITUTE(SUBSTITUTE(SUBSTITUTE(D29," ","-"),"/","-"),".",""),",","")),"") | D29: BOD 19 E.C.C3.L | E29: Bombas Hidráulicas | F29: SOHIPREN | H29: draft | I29: AGRALE | J29: TRATOR | K29: PRINCIPAL E DIREÇÃO | L29: 8013108327003-8009108575005-F000510708 | R29: =IFERROR(IF(AND(O29>0,P29>0,Q29>0),(O29*P29*Q29)/6000,""),"") | S29: =IFERROR(IF(AND(N29>0,R29>0),MAX(N29,R29),IF(N29>0,N29,IF(R29>0,R29,""))),"") | U29: FALTA | V29: 626 | W29: 0.3 | X29: =IFERROR(V29+T29,"") | Y29: =IFERROR(IF(W29<1,X29/(1-W29),""),"") | Z29: ='01_CONFIG_GLOBAL'!$C$14 | AA29: =IFERROR(Y29*Z29,"") | AB29: =IFERROR(IF(Z29<1,Y29/(1-Z29),""),"") | AI29: =IFERROR(AVERAGE(AD29,AF29,AH29),"") | AJ29: =IFERROR(IF(AI29="","sem dados",IF(AB29<AI29*0.95,"abaixo",IF(AB29>AI29*1.05,"acima","em linha"))),"") | AK29: não | AO29: =A29 | AP29: =D29
A30: 5.0220.L025261.0 | B30: L025261 | C30: =IFERROR(LOWER(SUBSTITUTE(SUBSTITUTE(SUBSTITUTE(SUBSTITUTE(D30," ","-"),"/","-"),".",""),",","")),"") | D30: BOMBA HIDRÁULICA - APLICAÇÃO 22,5 B1.P6.A/16.A42.L | E30: Bombas Hidráulicas | F30: SOHIPREN | H30: draft | I30: AGRALE | J30: TRATOR | K30: PRINCIPAL E DIREÇÃO | L30: F000510708-8013108327003-8009108575005 | R30: =IFERROR(IF(AND(O30>0,P30>0,Q30>0),(O30*P30*Q30)/6000,""),"") | S30: =IFERROR(IF(AND(N30>0,R30>0),MAX(N30,R30),IF(N30>0,N30,IF(R30>0,R30,""))),"") | U30: FALTA | V30: 1551.28 | W30: 0.3 | X30: =IFERROR(V30+T30,"") | Y30: =IFERROR(IF(W30<1,X30/(1-W30),""),"") | Z30: ='01_CONFIG_GLOBAL'!$C$14 | AA30: =IFERROR(Y30*Z30,"") | AB30: =IFERROR(IF(Z30<1,Y30/(1-Z30),""),"") | AI30: =IFERROR(AVERAGE(AD30,AF30,AH30),"") | AJ30: =IFERROR(IF(AI30="","sem dados",IF(AB30<AI30*0.95,"abaixo",IF(AB30>AI30*1.05,"acima","em linha"))),"") | AK30: não | AO30: =A30 | AP30: =D30
A31: 5.1621.0620001.0 | C31: =IFERROR(LOWER(SUBSTITUTE(SUBSTITUTE(SUBSTITUTE(SUBSTITUTE(D31," ","-"),"/","-"),".",""),",","")),"") | D31: BPB2-100-Y4 | F31: SOHIPREN | H31: draft | I31: AGRALE TRATORES | J31: TRATOR | K31: HIDROSTÁTICA | L31: 8009.1030.2000.7 | R31: =IFERROR(IF(AND(O31>0,P31>0,Q31>0),(O31*P31*Q31)/6000,""),"") | S31: =IFERROR(IF(AND(N31>0,R31>0),MAX(N31,R31),IF(N31>0,N31,IF(R31>0,R31,""))),"") | U31: FALTA | V31: 826.55 | W31: 0.3 | X31: =IFERROR(V31+T31,"") | Y31: =IFERROR(IF(W31<1,X31/(1-W31),""),"") | Z31: ='01_CONFIG_GLOBAL'!$C$14 | AA31: =IFERROR(Y31*Z31,"") | AB31: =IFERROR(IF(Z31<1,Y31/(1-Z31),""),"") | AI31: =IFERROR(AVERAGE(AD31,AF31,AH31),"") | AJ31: =IFERROR(IF(AI31="","sem dados",IF(AB31<AI31*0.95,"abaixo",IF(AB31>AI31*1.05,"acima","em linha"))),"") | AK31: não | AO31: =A31 | AP31: =D31
A32: 5.0220.0547229.0 | B32: 547229 | C32: =IFERROR(LOWER(SUBSTITUTE(SUBSTITUTE(SUBSTITUTE(SUBSTITUTE(D32," ","-"),"/","-"),".",""),",","")),"") | D32: BOMBA HIDRÁULICA - APLICAÇÃO 19 B9.B4.A11/16 A7.D7 18-90 BAR | E32: Bombas Hidráulicas | F32: SOHIPREN | H32: draft | I32: AGRALE TRATORES | J32: TRATOR | K32: PRINCIPAL E DIREÇÃO | R32: =IFERROR(IF(AND(O32>0,P32>0,Q32>0),(O32*P32*Q32)/6000,""),"") | S32: =IFERROR(IF(AND(N32>0,R32>0),MAX(N32,R32),IF(N32>0,N32,IF(R32>0,R32,""))),"") | U32: FALTA | V32: 1615 | W32: 0.3 | X32: =IFERROR(V32+T32,"") | Y32: =IFERROR(IF(W32<1,X32/(1-W32),""),"") | Z32: ='01_CONFIG_GLOBAL'!$C$14 | AA32: =IFERROR(Y32*Z32,"") | AB32: =IFERROR(IF(Z32<1,Y32/(1-Z32),""),"") | AI32: =IFERROR(AVERAGE(AD32,AF32,AH32),"") | AJ32: =IFERROR(IF(AI32="","sem dados",IF(AB32<AI32*0.95,"abaixo",IF(AB32>AI32*1.05,"acima","em linha"))),"") | AK32: não | AO32: =A32 | AP32: =D32
A33: 5.0205.0542404.0 | B33: 542404 | C33: =IFERROR(LOWER(SUBSTITUTE(SUBSTITUTE(SUBSTITUTE(SUBSTITUTE(D33," ","-"),"/","-"),".",""),",","")),"") | D33: BOD 8 B1.B10.A.L | E33: Bombas Hidráulicas | F33: SOHIPREN | H33: draft | I33: AGRALE TRATORES | J33: TRATOR | K33: PRINCIPAL | L33: 8008108132007-9510080401-11101008012-90605002 | R33: =IFERROR(IF(AND(O33>0,P33>0,Q33>0),(O33*P33*Q33)/6000,""),"") | S33: =IFERROR(IF(AND(N33>0,R33>0),MAX(N33,R33),IF(N33>0,N33,IF(R33>0,R33,""))),"") | U33: FALTA | V33: 778 | W33: 0.3 | X33: =IFERROR(V33+T33,"") | Y33: =IFERROR(IF(W33<1,X33/(1-W33),""),"") | Z33: ='01_CONFIG_GLOBAL'!$C$14 | AA33: =IFERROR(Y33*Z33,"") | AB33: =IFERROR(IF(Z33<1,Y33/(1-Z33),""),"") | AI33: =IFERROR(AVERAGE(AD33,AF33,AH33),"") | AJ33: =IFERROR(IF(AI33="","sem dados",IF(AB33<AI33*0.95,"abaixo",IF(AB33>AI33*1.05,"acima","em linha"))),"") | AK33: não | AO33: =A33 | AP33: =D33
A34: 5.0220.0547205.0 | B34: 547205 | C34: =IFERROR(LOWER(SUBSTITUTE(SUBSTITUTE(SUBSTITUTE(SUBSTITUTE(D34," ","-"),"/","-"),".",""),",","")),"") | D34: Bomba Hidráulica Principal Valtra-Valmet 880/980/1780 | E34: Bombas Hidráulicas | F34: SOHIPREN | H34: active | I34: AGRALE TRATORES - VALTRA | J34: TRATOR | K34: PRINCIPAL | L34: 8.008.1080.100.03/801661-10/9510080741/11112022005 | N34: 7.2 | O34: 30 | P34: 12.5 | Q34: 12.5 | R34: =IFERROR(IF(AND(O34>0,P34>0,Q34>0),(O34*P34*Q34)/6000,""),"") | S34: =IFERROR(IF(AND(N34>0,R34>0),MAX(N34,R34),IF(N34>0,N34,IF(R34>0,R34,""))),"") | T34: 100 | U34: fornecedor | V34: 1043.8 | W34: 0.2 | X34: =IFERROR(V34+T34,"") | Y34: =IFERROR(IF(W34<1,X34/(1-W34),""),"") | Z34: ='01_CONFIG_GLOBAL'!$C$14 | AA34: =IFERROR(Y34*Z34,"") | AB34: =IFERROR(IF(Z34<1,Y34/(1-Z34),""),"") | AI34: =IFERROR(AVERAGE(AD34,AF34,AH34),"") | AJ34: =IFERROR(IF(AI34="","sem dados",IF(AB34<AI34*0.95,"abaixo",IF(AB34>AI34*1.05,"acima","em linha"))),"") | AK34: sim | AN34: Fotos: assets/livenza_5.0220.0547205-CT_REV._0_p1.png | AO34: =A34 | AP34: =D34 | AQ34: 0029_547205_Livenza_5_0220_0547205-CT_0_att86_p1_foto_3d_ecommerce.png | 0029_547205_Livenza_5_0220_0547205-CT_0_att86_p1_desenho_tec.png | livenza_5.0220.0547205-CT_REV._0_p1.png
A35: 5.0202.0540014.0 | B35: 540014 | C35: =IFERROR(LOWER(SUBSTITUTE(SUBSTITUTE(SUBSTITUTE(SUBSTITUTE(D35," ","-"),"/","-"),".",""),",","")),"") | D35: BOMBA HIDRÁULICA - APLICAÇÃO 4 A.B9.A.L (CRUCETA) | E35: Bombas Hidráulicas | F35: SOHIPREN | H35: draft | I35: AMEISE | J35: EMPILHADEIRA ELETRICA | K35: PRINCIPAL | L35: 750298 | R35: =IFERROR(IF(AND(O35>0,P35>0,Q35>0),(O35*P35*Q35)/6000,""),"") | S35: =IFERROR(IF(AND(N35>0,R35>0),MAX(N35,R35),IF(N35>0,N35,IF(R35>0,R35,""))),"") | U35: FALTA | V35: 473 | W35: 0.3 | X35: =IFERROR(V35+T35,"") | Y35: =IFERROR(IF(W35<1,X35/(1-W35),""),"") | Z35: ='01_CONFIG_GLOBAL'!$C$14 | AA35: =IFERROR(Y35*Z35,"") | AB35: =IFERROR(IF(Z35<1,Y35/(1-Z35),""),"") | AI35: =IFERROR(AVERAGE(AD35,AF35,AH35),"") | AJ35: =IFERROR(IF(AI35="","sem dados",IF(AB35<AI35*0.95,"abaixo",IF(AB35>AI35*1.05,"acima","em linha"))),"") | AK35: não | AO35: =A35 | AP35: =D35
A36: 5.0206.0543269.0 | B36: 543269 | C36: =IFERROR(LOWER(SUBSTITUTE(SUBSTITUTE(SUBSTITUTE(SUBSTITUTE(D36," ","-"),"/","-"),".",""),",","")),"") | D36: BOMBA HIDRÁULICA - APLICAÇÃO 11 A.B9.A4.L (CRUCETA) | E36: Bombas Hidráulicas | F36: SOHIPREN | H36: draft | I36: AMEISE | J36: EMPILHADEIRA ELETRICA | K36: PRINCIPAL | L36: 750117 | R36: =IFERROR(IF(AND(O36>0,P36>0,Q36>0),(O36*P36*Q36)/6000,""),"") | S36: =IFERROR(IF(AND(N36>0,R36>0),MAX(N36,R36),IF(N36>0,N36,IF(R36>0,R36,""))),"") | U36: FALTA | V36: 517 | W36: 0.3 | X36: =IFERROR(V36+T36,"") | Y36: =IFERROR(IF(W36<1,X36/(1-W36),""),"") | Z36: ='01_CONFIG_GLOBAL'!$C$14 | AA36: =IFERROR(Y36*Z36,"") | AB36: =IFERROR(IF(Z36<1,Y36/(1-Z36),""),"") | AI36: =IFERROR(AVERAGE(AD36,AF36,AH36),"") | AJ36: =IFERROR(IF(AI36="","sem dados",IF(AB36<AI36*0.95,"abaixo",IF(AB36>AI36*1.05,"acima","em linha"))),"") | AK36: não | AO36: =A36 | AP36: =D36
A37: 5.0208.0544879.0 | B37: 544879 | C37: =IFERROR(LOWER(SUBSTITUTE(SUBSTITUTE(SUBSTITUTE(SUBSTITUTE(D37," ","-"),"/","-"),".",""),",","")),"") | D37: BOMBA HIDRÁULICA - APLICAÇÃO 16 A.B9.A4.L | E37: Bombas Hidráulicas | F37: SOHIPREN | H37: draft | I37: AMEISE | J37: EMPILHADEIRA ELETRICA | K37: PRINCIPAL | L37: 750083 | R37: =IFERROR(IF(AND(O37>0,P37>0,Q37>0),(O37*P37*Q37)/6000,""),"") | S37: =IFERROR(IF(AND(N37>0,R37>0),MAX(N37,R37),IF(N37>0,N37,IF(R37>0,R37,""))),"") | U37: FALTA | V37: 605 | W37: 0.3 | X37: =IFERROR(V37+T37,"") | Y37: =IFERROR(IF(W37<1,X37/(1-W37),""),"") | Z37: ='01_CONFIG_GLOBAL'!$C$14 | AA37: =IFERROR(Y37*Z37,"") | AB37: =IFERROR(IF(Z37<1,Y37/(1-Z37),""),"") | AI37: =IFERROR(AVERAGE(AD37,AF37,AH37),"") | AJ37: =IFERROR(IF(AI37="","sem dados",IF(AB37<AI37*0.95,"abaixo",IF(AB37>AI37*1.05,"acima","em linha"))),"") | AK37: não | AO37: =A37 | AP37: =D37
A38: 5.5205.0549529.0 | B38: 549529 | C38: =IFERROR(LOWER(SUBSTITUTE(SUBSTITUTE(SUBSTITUTE(SUBSTITUTE(D38," ","-"),"/","-"),".",""),",","")),"") | D38: MRBO 8 C11.C.C3.L | F38: SOHIPREN | H38: draft | I38: ANDRADE | J38: BOMBA D'AGUA | K38: MOTOR HIDRÁULICO | L38: 28685/0513013715 | R38: =IFERROR(IF(AND(O38>0,P38>0,Q38>0),(O38*P38*Q38)/6000,""),"") | S38: =IFERROR(IF(AND(N38>0,R38>0),MAX(N38,R38),IF(N38>0,N38,IF(R38>0,R38,""))),"") | U38: FALTA | V38: 767.8 | W38: 0.3 | X38: =IFERROR(V38+T38,"") | Y38: =IFERROR(IF(W38<1,X38/(1-W38),""),"") | Z38: ='01_CONFIG_GLOBAL'!$C$14 | AA38: =IFERROR(Y38*Z38,"") | AB38: =IFERROR(IF(Z38<1,Y38/(1-Z38),""),"") | AI38: =IFERROR(AVERAGE(AD38,AF38,AH38),"") | AJ38: =IFERROR(IF(AI38="","sem dados",IF(AB38<AI38*0.95,"abaixo",IF(AB38>AI38*1.05,"acima","em linha"))),"") | AK38: não | AO38: =A38 | AP38: =D38
A39: 5.5209.L008060.0 | B39: L00806 | C39: =IFERROR(LOWER(SUBSTITUTE(SUBSTITUTE(SUBSTITUTE(SUBSTITUTE(D39," ","-"),"/","-"),".",""),",","")),"") | D39: MUD BO 8 C11.C.G.BL (2734) | F39: SOHIPREN | H39: draft | I39: ANDRADE | J39: BOMLBA TASP | K39: ACIONAMENTO BOMBA D'AGUA | R39: =IFERROR(IF(AND(O39>0,P39>0,Q39>0),(O39*P39*Q39)/6000,""),"") | S39: =IFERROR(IF(AND(N39>0,R39>0),MAX(N39,R39),IF(N39>0,N39,IF(R39>0,R39,""))),"") | U39: FALTA | V39: 428.93 | W39: 0.3 | X39: =IFERROR(V39+T39,"") | Y39: =IFERROR(IF(W39<1,X39/(1-W39),""),"") | Z39: ='01_CONFIG_GLOBAL'!$C$14 | AA39: =IFERROR(Y39*Z39,"") | AB39: =IFERROR(IF(Z39<1,Y39/(1-Z39),""),"") | AI39: =IFERROR(AVERAGE(AD39,AF39,AH39),"") | AJ39: =IFERROR(IF(AI39="","sem dados",IF(AB39<AI39*0.95,"abaixo",IF(AB39>AI39*1.05,"acima","em linha"))),"") | AK39: não | AO39: =A39 | AP39: =D39
A40: 5.5209.L009930.0 | B40: L00993 | C40: =IFERROR(LOWER(SUBSTITUTE(SUBSTITUTE(SUBSTITUTE(SUBSTITUTE(D40," ","-"),"/","-"),".",""),",","")),"") | D40: MUI BO 8 C11.C.G.BL (2734) | F40: SOHIPREN | H40: draft | I40: ANDRADE | J40: IRRIGADOR | K40: ACIONAMENTO BOMBA D'AGUA | R40: =IFERROR(IF(AND(O40>0,P40>0,Q40>0),(O40*P40*Q40)/6000,""),"") | S40: =IFERROR(IF(AND(N40>0,R40>0),MAX(N40,R40),IF(N40>0,N40,IF(R40>0,R40,""))),"") | U40: FALTA | V40: 790 | W40: 0.3 | X40: =IFERROR(V40+T40,"") | Y40: =IFERROR(IF(W40<1,X40/(1-W40),""),"") | Z40: ='01_CONFIG_GLOBAL'!$C$14 | AA40: =IFERROR(Y40*Z40,"") | AB40: =IFERROR(IF(Z40<1,Y40/(1-Z40),""),"") | AI40: =IFERROR(AVERAGE(AD40,AF40,AH40),"") | AJ40: =IFERROR(IF(AI40="","sem dados",IF(AB40<AI40*0.95,"abaixo",IF(AB40>AI40*1.05,"acima","em linha"))),"") | AK40: não | AO40: =A40 | AP40: =D40
A41: 5.5206.L010450.0 | B41: L01045 | C41: =IFERROR(LOWER(SUBSTITUTE(SUBSTITUTE(SUBSTITUTE(SUBSTITUTE(D41," ","-"),"/","-"),".",""),",","")),"") | D41: MUD BO 11 E18.C.G.BL (2734) | F41: SOHIPREN | H41: draft | I41: ANDRADE | J41: IRRIGADOR | K41: ACIONAMENTO BOMBA D'AGUA | R41: =IFERROR(IF(AND(O41>0,P41>0,Q41>0),(O41*P41*Q41)/6000,""),"") | S41: =IFERROR(IF(AND(N41>0,R41>0),MAX(N41,R41),IF(N41>0,N41,IF(R41>0,R41,""))),"") | U41: FALTA | V41: 708 | W41: 0.3 | X41: =IFERROR(V41+T41,"") | Y41: =IFERROR(IF(W41<1,X41/(1-W41),""),"") | Z41: ='01_CONFIG_GLOBAL'!$C$14 | AA41: =IFERROR(Y41*Z41,"") | AB41: =IFERROR(IF(Z41<1,Y41/(1-Z41),""),"") | AI41: =IFERROR(AVERAGE(AD41,AF41,AH41),"") | AJ41: =IFERROR(IF(AI41="","sem dados",IF(AB41<AI41*0.95,"abaixo",IF(AB41>AI41*1.05,"acima","em linha"))),"") | AK41: não | AO41: =A41 | AP41: =D41
...

Sheet 03_AGCO
A1: APP — Agro Peças Padrão | Master 05_AGCO
A2: Total de SKUs: | B2: =COUNTA(A6:A99997) | D2: Faltando embalagem: | E2: =COUNTIF(X6:X99997,"FALTA") | G2: Cadastrados Shopify: | H2: =COUNTIF(AN6:AN99997,"sim") | J2: Divergentes: | K2: =COUNTIF(AN6:AN99997,"divergente")
A4: IDENTIFICAÇÃO | I4: APLICAÇÃO TÉCNICA | P4: LOGÍSTICA E EMBALAGEM | Y4: CUSTO E PRECIFICAÇÃO | AF4: PESQUISA DE MERCADO | AN4: WORKFLOW
A5: SKU / Código | B5: Part Number | C5: Handle (Shopify) | D5: Title (PT-BR) | E5: Product Type | F5: Vendor (Fabricante) | G5: Tags (vírgula) | H5: Status | I5: Montadora compatível | J5: Equipamento / Modelo | K5: Função / Aplicação | L5: Códigos cruzados | M5: NCM | N5: Qtde KIT | O5: Lead Time | P5: Peso (kg) | Q5: Comprimento (cm) | R5: Largura (cm) | S5: Altura (cm) | T5: Peso cubado (kg) KIT | U5: Peso cubado (kg) | V5: Peso considerado (kg) | W5: Frete fábrica → eCom () | X5: Origem do dado embalagem | Y5: Custo unitário () | Z5: % Margem de lucro | AA5: Custo + frete inbound () | AB5: Preço c/ margem () | AC5: Taxa Mercado Pago (%) | AD5: Taxa MP () | AE5: Preço final site () | AF5: Concorrente 1 — Nome | AG5: Concorrente 1 — Preço () | AH5: Concorrente 2 — Nome | AI5: Concorrente 2 — Preço () | AJ5: Concorrente 3 — Nome | AK5: Concorrente 3 — Preço () | AL5: Preço médio concorrência () | AM5: Posicionamento | AN5: Cadastrado Shopify? | AO5: Última atualização | AP5: Operador responsável | AQ5: Instruções | AR5: Observações | AS5: SKU Shopify (derivado) | AT5: Título Shopify (derivado) | AU5: Imagens site (assets)
A6: ACX3266690 | B6: ACX3266690 | C6: =IFERROR(LOWER(SUBSTITUTE(SUBSTITUTE(SUBSTITUTE(SUBSTITUTE(D6," ","-"),"/","-"),".",""),",","")),"") | D6: Suporte do Dosador - AGCO ACX3266690 | Plantadeira Momentum | E6: Peças Plásticas Injetadas | F6: APP | H6: active | I6: AGCO | J6: PLANTADEIRA | K6: =LOWER(CONCATENATE(E6," ",J6," ",D6)) | M6: 84329000 | N6: 1 | O6: 5 | P6: 0.36 | Q6: 12 | R6: 3 | S6: 6 | T6: =IFERROR(IF(AND(Q6>0,R6>0,S6>0),(Q6*R6*S6)/6000,""),"") | U6: =IFERROR(IF(AND(Q6>0,R6>0,S6>0),(Q6*R6*S6)/6000,""),"") | V6: =IFERROR(IF(AND(P6>0,U6>0),MAX(P6,U6),IF(P6>0,P6,IF(U6>0,U6,""))),"") | W6: 16.75 | X6: fornecedor | Y6: 100.96 | Z6: 0.2 | AA6: =IFERROR(Y6+W6,"") | AB6: =IFERROR(IF(Z6<1,AA6/(1-Z6),""),"") | AC6: ='01_CONFIG_GLOBAL'!$C$14 | AD6: =IFERROR(AB6*AC6,"") | AE6: =IFERROR(IF(AC6<1,AB6/(1-AC6),""),"") | AL6: =IFERROR(AVERAGE(AG6,AI6,AK6),"") | AM6: =IFERROR(IF(AL6="","sem dados",IF(AE6<AL6*0.95,"abaixo",IF(AE6>AL6*1.05,"acima","em linha"))),"") | AN6: sim | AR6: Fotos: assets/agco_ACX3266690_ecommerce_1.png; assets/agco_ACX3266690_ecommerce_2.png; assets/agco_ACX3266690_ecommerce_3.png | AS6: =IF(AND(N6<>"",N6>1),A6&"-KIT"&N6,A6) | AT6: =IF(AND(N6<>"",N6>1),D6&" — Kit "&N6&" unidades",D6) | AU6: agco_ACX3266690_ecommerce_1.png | agco_ACX3266690_ecommerce_2.png | agco_ACX3266690_ecommerce_3.png
A7: ACW0551840 | B7: ACW0551840 | C7: =IFERROR(LOWER(SUBSTITUTE(SUBSTITUTE(SUBSTITUTE(SUBSTITUTE(D7," ","-"),"/","-"),".",""),",","")),"") | D7: Condutor de Sementes para Sensor - AGCO ACW0551840 | E7: Peças Plásticas Injetadas | F7: APP | H7: active | I7: AGCO | J7: PLANTADEIRA | K7: =LOWER(CONCATENATE(E7," ",J7," ",D7)) | M7: 84329000 | N7: 1 | O7: 5 | P7: 0.35 | Q7: 50 | R7: 7 | S7: 4.5 | T7: =IFERROR(IF(AND(Q7>0,R7>0,S7>0),(Q7*R7*S7)/6000,""),"") | U7: =IFERROR(IF(AND(Q7>0,R7>0,S7>0),(Q7*R7*S7)/6000,""),"") | V7: =IFERROR(IF(AND(P7>0,U7>0),MAX(P7,U7),IF(P7>0,P7,IF(U7>0,U7,""))),"") | W7: 2.21 | X7: fornecedor | Y7: 9.15 | Z7: 0.2 | AA7: =IFERROR(Y7+W7,"") | AB7: =IFERROR(IF(Z7<1,AA7/(1-Z7),""),"") | AC7: ='01_CONFIG_GLOBAL'!$C$14 | AD7: =IFERROR(AB7*AC7,"") | AE7: =IFERROR(IF(AC7<1,AB7/(1-AC7),""),"") | AL7: =IFERROR(AVERAGE(AG7,AI7,AK7),"") | AM7: =IFERROR(IF(AL7="","sem dados",IF(AE7<AL7*0.95,"abaixo",IF(AE7>AL7*1.05,"acima","em linha"))),"") | AN7: sim | AR7: Fotos: assets/agco_ACW0551840_ecommerce_1.png; assets/agco_ACW0551840_ecommerce_2.png | CORRIGIDO 21/07: peso 3,5kg impossível p/ conduto plástico — estimado 0,35kg (verificar balança) | AS7: =IF(AND(N7<>"",N7>1),A7&"-KIT"&N7,A7) | AT7: =IF(AND(N7<>"",N7>1),D7&" — Kit "&N7&" unidades",D7) | AU7: agco_ACW0551840_ecommerce_1.png | agco_ACW0551840_ecommerce_2.png
A8: ACW0551840 | B8: ACW0551840 | C8: =IFERROR(LOWER(SUBSTITUTE(SUBSTITUTE(SUBSTITUTE(SUBSTITUTE(D8," ","-"),"/","-"),".",""),",","")),"") | D8: Condutor de Sementes para Sensor - Kit 25 Unidades - AGCO ACW0551840 | E8: Peças Plásticas Injetadas | F8: APP | H8: active | I8: AGCO | J8: PLANTADEIRA | K8: =LOWER(CONCATENATE(E8," ",J8," ",D8)) | M8: 84329000 | N8: 25 | O8: 5 | P8: =P7*N8 | Q8: 50 | R8: 25 | S8: 50 | T8: =IFERROR(IF(AND(Q8>0,R8>0,S8>0),(Q8*R8*S8)/6000,""),"") | U8: =IFERROR(IF(AND(Q8>0,R8>0,S8>0),(Q8*R8*S8)/6000,""),"") | V8: =IFERROR(IF(AND(P8>0,U8>0),MAX(P8,U8),IF(P8>0,P8,IF(U8>0,U8,""))),"") | W8: 55.23 | X8: fornecedor | Y8: 228.75 | Z8: 0.2 | AA8: =IFERROR(Y8+W8,"") | AB8: =IFERROR(IF(Z8<1,AA8/(1-Z8),""),"") | AC8: ='01_CONFIG_GLOBAL'!$C$14 | AD8: =IFERROR(AB8*AC8,"") | AE8: =IFERROR(IF(AC8<1,AB8/(1-AC8),""),"") | AM8: =IFERROR(IF(AL8="","sem dados",IF(AE8<AL8*0.95,"abaixo",IF(AE8>AL8*1.05,"acima","em linha"))),"") | AN8: sim | AR8: peso kit recalculado após correção do peso unitário | AS8: =IF(AND(N8<>"",N8>1),A8&"-KIT"&N8,A8) | AT8: =IF(AND(N8<>"",N8>1),D8&" — Kit "&N8&" unidades",D8) | AU8: agco_ACW0551840_ecommerce_1.png | agco_ACW0551840_ecommerce_2.png
A9: ACX2865730 | B9: ACX2865730 | C9: =IFERROR(LOWER(SUBSTITUTE(SUBSTITUTE(SUBSTITUTE(SUBSTITUTE(D9," ","-"),"/","-"),".",""),",","")),"") | D9: Tampa do Módulo SRM - Kit 60 Unidades - AGCO ACX2865730 | E9: Peças Plásticas Injetadas | F9: APP | H9: active | I9: AGCO | J9: PLANTADEIRA | K9: =LOWER(CONCATENATE(E9," ",J9," ",D9)) | M9: 84329000 | N9: 60 | O9: 5 | P9: 22.4 | Q9: 35 | R9: 43 | S9: 50 | T9: =IFERROR(IF(AND(Q9>0,R9>0,S9>0),(Q9*R9*S9)/6000,""),"") | U9: =IFERROR(IF(AND(Q9>0,R9>0,S9>0),(Q9*R9*S9)/6000,""),"") | V9: =IFERROR(IF(AND(P9>0,U9>0),MAX(P9,U9),IF(P9>0,P9,IF(U9>0,U9,""))),"") | W9: 105.71 | X9: fornecedor | Y9: =10.02*N9 | Z9: 0.2 | AA9: =IFERROR(Y9+W9,"") | AB9: =IFERROR(IF(Z9<1,AA9/(1-Z9),""),"") | AC9: ='01_CONFIG_GLOBAL'!$C$14 | AD9: =IFERROR(AB9*AC9,"") | AE9: =IFERROR(IF(AC9<1,AB9/(1-AC9),""),"") | AL9: =IFERROR(AVERAGE(AG9,AI9,AK9),"") | AM9: =IFERROR(IF(AL9="","sem dados",IF(AE9<AL9*0.95,"abaixo",IF(AE9>AL9*1.05,"acima","em linha"))),"") | AN9: sim | AS9: =IF(AND(N9<>"",N9>1),A9&"-KIT"&N9,A9) | AT9: =IF(AND(N9<>"",N9>1),D9&" — Kit "&N9&" unidades",D9) | AU9: SEM IMAGEM
A10: ACX3454710 | B10: ACX3454710 | C10: =IFERROR(LOWER(SUBSTITUTE(SUBSTITUTE(SUBSTITUTE(SUBSTITUTE(D10," ","-"),"/","-"),".",""),",","")),"") | D10: Conjunto Montado Reservatório de Sementes Mecânico - AGCO ACX3454710 | E10: Peças Plásticas Injetadas | F10: APP | H10: draft | I10: AGCO | J10: PLANTADEIRA | K10: =LOWER(CONCATENATE(E10," ",J10," ",D10)) | M10: 84329000 | N10: 25 | O10: 5 | P10: 32.5 | Q10: 100 | R10: 120 | S10: 72 | T10: =IFERROR(IF(AND(Q10>0,R10>0,S10>0),(Q10*R10*S10)/6000,""),"") | U10: =IFERROR(IF(AND(Q10>0,R10>0,S10>0),(Q10*R10*S10)/6000,""),"") | V10: =IFERROR(IF(AND(P10>0,U10>0),MAX(P10,U10),IF(P10>0,P10,IF(U10>0,U10,""))),"") | W10: 1609.15 | X10: fornecedor | Y10: =Y11*N10 | Z10: 0.2 | AA10: =IFERROR(Y10+W10,"") | AB10: =IFERROR(IF(Z10<1,AA10/(1-Z10),""),"") | AC10: ='01_CONFIG_GLOBAL'!$C$14 | AD10: =IFERROR(AB10*AC10,"") | AE10: =IFERROR(IF(AC10<1,AB10/(1-AC10),""),"") | AL10: =IFERROR(AVERAGE(AG10,AI10,AK10),"") | AM10: =IFERROR(IF(AL10="","sem dados",IF(AE10<AL10*0.95,"abaixo",IF(AE10>AL10*1.05,"acima","em linha"))),"") | AN10: sim | AR10: Fotos: assets/agco_ACX3454710_ecommerce_1.png; assets/agco_ACX3454710_ecommerce_2.png; assets/agco_ACX3454710_ecommerce_3.png; assets/agco_ACX3454710_ecommerce_4.png | DRAFT 21/07: frete parcel inviável (R$1609/R$645 cotados p/ caixa-palete) — cotar transportadora de carga antes de publicar | AS10: =IF(AND(N10<>"",N10>1),A10&"-KIT"&N10,A10) | AT10: =IF(AND(N10<>"",N10>1),D10&" — Kit "&N10&" unidades",D10) | AU10: agco_ACX3454710_ecommerce_1.png | agco_ACX3454710_ecommerce_2.png | agco_ACX3454710_ecommerce_3.png | agco_ACX3454710_ecommerce_4.png
A11: ACX3454710 | B11: ACX3454710 | C11: =IFERROR(LOWER(SUBSTITUTE(SUBSTITUTE(SUBSTITUTE(SUBSTITUTE(D11," ","-"),"/","-"),".",""),",","")),"") | D11: Conjunto Montado Reservatório de Sementes Mecânico - AGCO ACX3454710 | E11: Peças Plásticas Injetadas | F11: APP | H11: active | I11: AGCO | J11: PLANTADEIRA | K11: =LOWER(CONCATENATE(E11," ",J11," ",D11)) | M11: 84329000 | N11: 1 | O11: 5 | P11: 1.3 | Q11: 31 | R11: 25 | S11: 25 | T11: =IFERROR(IF(AND(Q11>0,R11>0,S11>0),(Q11*R11*S11)/6000,""),"") | U11: =IFERROR(IF(AND(Q11>0,R11>0,S11>0),(Q11*R11*S11)/6000,""),"") | V11: =IFERROR(IF(AND(P11>0,U11>0),MAX(P11,U11),IF(P11>0,P11,IF(U11>0,U11,""))),"") | W11: 40.06 | X11: fornecedor | Y11: 35.74 | Z11: 0.2 | AA11: =IFERROR(Y11+W11,"") | AB11: =IFERROR(IF(Z11<1,AA11/(1-Z11),""),"") | AC11: ='01_CONFIG_GLOBAL'!$C$14 | AD11: =IFERROR(AB11*AC11,"") | AE11: =IFERROR(IF(AC11<1,AB11/(1-AC11),""),"") | AL11: =IFERROR(AVERAGE(AG11,AI11,AK11),"") | AM11: =IFERROR(IF(AL11="","sem dados",IF(AE11<AL11*0.95,"abaixo",IF(AE11>AL11*1.05,"acima","em linha"))),"") | AN11: sim | AR11: Fotos: assets/agco_ACX3454710_ecommerce_1.png; assets/agco_ACX3454710_ecommerce_2.png; assets/agco_ACX3454710_ecommerce_3.png; assets/agco_ACX3454710_ecommerce_4.png | frete mantido no valor anterior (40,06) — rateio via palete suspenso | AS11: =IF(AND(N11<>"",N11>1),A11&"-KIT"&N11,A11) | AT11: =IF(AND(N11<>"",N11>1),D11&" — Kit "&N11&" unidades",D11) | AU11: agco_ACX3454710_ecommerce_1.png | agco_ACX3454710_ecommerce_2.png | agco_ACX3454710_ecommerce_3.png | agco_ACX3454710_ecommerce_4.png
A12: ACX3454710 | B12: ACX3454710 | C12: =IFERROR(LOWER(SUBSTITUTE(SUBSTITUTE(SUBSTITUTE(SUBSTITUTE(D12," ","-"),"/","-"),".",""),",","")),"") | D12: Conjunto Montado Reservatório de Sementes Mecânico - AGCO ACX3454710 | E12: Peças Plásticas Injetadas | F12: APP | H12: draft | I12: AGCO | J12: PLANTADEIRA | K12: =LOWER(CONCATENATE(E12," ",J12," ",D12)) | M12: 84329000 | N12: 12 | O12: 5 | P12: =P11*N12 | Q12: 100 | R12: 60 | S12: 60 | T12: =IFERROR(IF(AND(Q12>0,R12>0,S12>0),(Q12*R12*S12)/6000,""),"") | U12: =IFERROR(IF(AND(Q12>0,R12>0,S12>0),(Q12*R12*S12)/6000,""),"") | V12: =IFERROR(IF(AND(P12>0,U12>0),MAX(P12,U12),IF(P12>0,P12,IF(U12>0,U12,""))),"") | W12: 644.59 | X12: fornecedor | Y12: =Y11*N12 | Z12: 0.2 | AA12: =IFERROR(Y12+W12,"") | AB12: =IFERROR(IF(Z12<1,AA12/(1-Z12),""),"") | AC12: ='01_CONFIG_GLOBAL'!$C$14 | AD12: =IFERROR(AB12*AC12,"") | AE12: =IFERROR(IF(AC12<1,AB12/(1-AC12),""),"") | AM12: =IFERROR(IF(AL12="","sem dados",IF(AE12<AL12*0.95,"abaixo",IF(AE12>AL12*1.05,"acima","em linha"))),"") | AN12: sim | AS12: =IF(AND(N12<>"",N12>1),A12&"-KIT"&N12,A12) | AT12: =IF(AND(N12<>"",N12>1),D12&" — Kit "&N12&" unidades",D12) | AU12: agco_ACX3454710_ecommerce_1.png | agco_ACX3454710_ecommerce_2.png | agco_ACX3454710_ecommerce_3.png | agco_ACX3454710_ecommerce_4.png
A13: ACX2719210 | B13: ACX2719210 | C13: =IFERROR(LOWER(SUBSTITUTE(SUBSTITUTE(SUBSTITUTE(SUBSTITUTE(D13," ","-"),"/","-"),".",""),",","")),"") | D13: Conjunto Montado Joelho - AGCO ACX2719210 | E13: Peças Plásticas Injetadas | F13: APP | H13: active | I13: AGCO | J13: PLANTADEIRA | K13: =LOWER(CONCATENATE(E13," ",J13," ",D13)) | M13: 84329000 | N13: 1 | O13: 5 | P13: 0.2 | Q13: 4.4 | R13: 16.3 | S13: 9.2 | T13: =IFERROR(IF(AND(Q13>0,R13>0,S13>0),(Q13*R13*S13)/6000,""),"") | U13: =IFERROR(IF(AND(Q13>0,R13>0,S13>0),(Q13*R13*S13)/6000,""),"") | V13: =IFERROR(IF(AND(P13>0,U13>0),MAX(P13,U13),IF(P13>0,P13,IF(U13>0,U13,""))),"") | W13: 1.12 | X13: fornecedor | Y13: 13.81 | Z13: 0.2 | AA13: =IFERROR(Y13+W13,"") | AB13: =IFERROR(IF(Z13<1,AA13/(1-Z13),""),"") | AC13: ='01_CONFIG_GLOBAL'!$C$14 | AD13: =IFERROR(AB13*AC13,"") | AE13: =IFERROR(IF(AC13<1,AB13/(1-AC13),""),"") | AL13: =IFERROR(AVERAGE(AG13,AI13,AK13),"") | AM13: =IFERROR(IF(AL13="","sem dados",IF(AE13<AL13*0.95,"abaixo",IF(AE13>AL13*1.05,"acima","em linha"))),"") | AN13: sim | AS13: =IF(AND(N13<>"",N13>1),A13&"-KIT"&N13,A13) | AT13: =IF(AND(N13<>"",N13>1),D13&" — Kit "&N13&" unidades",D13) | AU13: AGCO_ACX2719210_ecommerce_1.png | AGCO_ACX2719210_ecommerce_2.png
A14: ACX2719210 | B14: ACX2719210 | C14: =IFERROR(LOWER(SUBSTITUTE(SUBSTITUTE(SUBSTITUTE(SUBSTITUTE(D14," ","-"),"/","-"),".",""),",","")),"") | D14: Conjunto Montado Joelho - Kit 30 Unidades - AGCO ACX2719210 | E14: Peças Plásticas Injetadas | F14: APP | H14: active | I14: AGCO | J14: PLANTADEIRA | K14: =LOWER(CONCATENATE(E14," ",J14," ",D14)) | M14: 84329000 | N14: 30 | O14: 5 | P14: =P13*N14 | Q14: 50 | R14: 18 | S14: 32 | T14: =IFERROR(IF(AND(Q14>0,R14>0,S14>0),(Q14*R14*S14)/6000,""),"") | U14: =IFERROR(IF(AND(Q14>0,R14>0,S14>0),(Q14*R14*S14)/6000,""),"") | V14: =IFERROR(IF(AND(P14>0,U14>0),MAX(P14,U14),IF(P14>0,P14,IF(U14>0,U14,""))),"") | W14: 33.55 | X14: fornecedor | Y14: =Y13*N14 | Z14: 0.2 | AA14: =IFERROR(Y14+W14,"") | AB14: =IFERROR(IF(Z14<1,AA14/(1-Z14),""),"") | AC14: ='01_CONFIG_GLOBAL'!$C$14 | AD14: =IFERROR(AB14*AC14,"") | AE14: =IFERROR(IF(AC14<1,AB14/(1-AC14),""),"") | AM14: =IFERROR(IF(AL14="","sem dados",IF(AE14<AL14*0.95,"abaixo",IF(AE14>AL14*1.05,"acima","em linha"))),"") | AN14: sim | AS14: =IF(AND(N14<>"",N14>1),A14&"-KIT"&N14,A14) | AT14: =IF(AND(N14<>"",N14>1),D14&" — Kit "&N14&" unidades",D14) | AU14: AGCO_ACX2719210_ecommerce_1.png | AGCO_ACX2719210_ecommerce_2.png
A15: 4383927M4 | B15: 4383927M4 | C15: =IFERROR(LOWER(SUBSTITUTE(SUBSTITUTE(SUBSTITUTE(SUBSTITUTE(D15," ","-"),"/","-"),".",""),",","")),"") | D15: Dobradiça Esquerda Inferior - Massey Ferguson 4383927M4 | E15: Peças Plásticas Injetadas | F15: APP | H15: active | I15: AGCO | J15: TRATOR | K15: =LOWER(CONCATENATE(E15," ",J15," ",D15)) | M15: 84329000 | N15: 1 | O15: 5 | P15: 0.19 | Q15: 3 | R15: 12.5 | S15: 8 | T15: =IFERROR(IF(AND(Q15>0,R15>0,S15>0),(Q15*R15*S15)/6000,""),"") | U15: =IFERROR(IF(AND(Q15>0,R15>0,S15>0),(Q15*R15*S15)/6000,""),"") | V15: =IFERROR(IF(AND(P15>0,U15>0),MAX(P15,U15),IF(P15>0,P15,IF(U15>0,U15,""))),"") | W15: 2.08 | X15: fornecedor | Y15: 20.01 | Z15: 0.2 | AA15: =IFERROR(Y15+W15,"") | AB15: =IFERROR(IF(Z15<1,AA15/(1-Z15),""),"") | AC15: ='01_CONFIG_GLOBAL'!$C$14 | AD15: =IFERROR(AB15*AC15,"") | AE15: =IFERROR(IF(AC15<1,AB15/(1-AC15),""),"") | AL15: =IFERROR(AVERAGE(AG15,AI15,AK15),"") | AM15: =IFERROR(IF(AL15="","sem dados",IF(AE15<AL15*0.95,"abaixo",IF(AE15>AL15*1.05,"acima","em linha"))),"") | AN15: sim | AR15: Fotos: assets/AGCO_4383927M4_ecommerce_1.png; assets/AGCO_4383927M4_ecommerce_2.png | AS15: =IF(AND(N15<>"",N15>1),A15&"-KIT"&N15,A15) | AT15: =IF(AND(N15<>"",N15>1),D15&" — Kit "&N15&" unidades",D15) | AU15: AGCO_4383927M4_ecommerce_1.png | AGCO_4383927M4_ecommerce_2.png
A16: 4383927M4 | B16: 4383927M4 | C16: =IFERROR(LOWER(SUBSTITUTE(SUBSTITUTE(SUBSTITUTE(SUBSTITUTE(D16," ","-"),"/","-"),".",""),",","")),"") | D16: Dobradiça Esquerda Inferior - Kit 10 Unidades - Massey Ferguson 4383927M4 | E16: Peças Plásticas Injetadas | F16: APP | H16: active | I16: AGCO | J16: TRATOR | K16: =LOWER(CONCATENATE(E16," ",J16," ",D16)) | M16: 84329000 | N16: 10 | O16: 5 | P16: =P15*N16 | Q16: 35 | R16: 15 | S16: 10 | T16: =IFERROR(IF(AND(Q16>0,R16>0,S16>0),(Q16*R16*S16)/6000,""),"") | U16: =IFERROR(IF(AND(Q16>0,R16>0,S16>0),(Q16*R16*S16)/6000,""),"") | V16: =IFERROR(IF(AND(P16>0,U16>0),MAX(P16,U16),IF(P16>0,P16,IF(U16>0,U16,""))),"") | W16: 20.77 | X16: fornecedor | Y16: =Y15*N16 | Z16: 0.2 | AA16: =IFERROR(Y16+W16,"") | AB16: =IFERROR(IF(Z16<1,AA16/(1-Z16),""),"") | AC16: ='01_CONFIG_GLOBAL'!$C$14 | AD16: =IFERROR(AB16*AC16,"") | AE16: =IFERROR(IF(AC16<1,AB16/(1-AC16),""),"") | AM16: =IFERROR(IF(AL16="","sem dados",IF(AE16<AL16*0.95,"abaixo",IF(AE16>AL16*1.05,"acima","em linha"))),"") | AN16: sim | AS16: =IF(AND(N16<>"",N16>1),A16&"-KIT"&N16,A16) | AT16: =IF(AND(N16<>"",N16>1),D16&" — Kit "&N16&" unidades",D16) | AU16: AGCO_4383927M4_ecommerce_1.png | AGCO_4383927M4_ecommerce_2.png
