Workbook

Sheet ⚙ Configurações
A1: ⚙ CONFIGURAÇÕES GLOBAIS — APP Agro Peças Padrão
A3: CUSTOS OPERACIONAIS (% sobre Custo de Aquisição)
A4: Overhead operacional (aluguel, salários, energia) | B4: 0.18 | C4: 18% sobre o custo de aquisição — ajuste conforme DRE
A5: Embalagem e manuseio | B5: 0.03 | C5: 3% sobre CA — inclui caixas, fita, etiqueta, NF
A6: Comissão / marketplace / taxa Shopify | B6: 0.025 | C6: 2.5% — taxa de gateway + plataforma
A7: Impostos sobre venda (Simples Nacional) | B7: 0.06 | C7: 6% médio Simples Nacional — verifique sua faixa
A8: Inadimplência / perdas estimadas | B8: 0.01 | C8: 1% — provisão para devoluções e perdas
A10: MARGENS DE LUCRO SUGERIDAS POR CATEGORIA
A11: Bombas Hidráulicas — margem mínima sobre venda | B11: 0.35 | C11: 35% — produtos de alto valor, menor giro
A12: Sensores / GPS / Monitores — margem mínima | B12: 0.4 | C12: 40% — produtos tech, margem maior
A13: Peças Plásticas / Plantadeira — margem mínima | B13: 0.45 | C13: 45% — alto giro, margens maiores
A14: Margem de segurança adicional (concorrência) | B14: 0.05 | C14: 5% extra para absorver variações de câmbio e insumos
A16: FRETE FÁBRICA → APP (Curitiba-PR)
A17: LIVENZA/Sohipren (origem: SP ou importado) | B17: 0.05 | C17: ~5% sobre PF — frete CIF/FOB Curitiba, peso médio 7kg
A18: Greco Agro Tech (origem: SP ou PR) | B18: 0.04 | C18: ~4% sobre PF — peças leves, frete mais barato
A19: AGCO / ADG (origem: SP) | B19: 0.045 | C19: ~4.5% sobre PF — peças médias/grandes
A20: ICMS interestadual médio (SP→PR) | B20: 0.07 | C20: 7% — verifique DIFAL e NCM de cada produto
A22: FRETE APP → CLIENTE — BASE POR REGIÃO (R$/pedido)
A23: Sul próximo (PR) — base até 3kg | B23: 25 | C23: Transportadora regional: Jamef, Braspress, TNT
A24: Sul (SC, RS) — base até 3kg | B24: 38
A25: Sudeste (SP, MG, RJ, ES) — base até 3kg | B25: 48
A26: Centro-Oeste (MT, MS, GO, DF) — base até 3kg | B26: 62
A27: Nordeste (BA, SE, AL, PE, PB, RN, CE, PI, MA) — base | B27: 85
A28: Norte (PA, AM, TO, RO, AC, RR, AP) — base até 3kg | B28: 110 | C28: Correios ou transportadora regional
A29: Acréscimo por kg adicional acima de 3kg (R$/kg) | B29: 14 | C29: Média nacional para produtos industriais
A30: Seguro mínimo (R$) | B30: 10 | C30: Valor mínimo de seguro por envio
A31: Seguro % sobre NF | B31: 0.004 | C31: 0,4% do valor declarado — incluso nas transportadoras sérias
A33: 📌 COMO USAR: 1. Ajuste os valores em amarelo conforme sua realidade financeira. 2. Na aba '💰 Formação de Preço', preencha APENAS as colunas amarelas (Preço de Fábrica, Markup desejado, Preço mín./máx. mercado). 3. Todas as colunas verdes são calculadas automaticamente por fórmula. 4. Na aba '🛒 Exportação Shopify', copie e cole no arquivo master_products_import.csv para subir preços em lote.

Sheet 💰 Formação de Preço
A1: 💰 TABELA MESTRA DE FORMAÇÃO DE PREÇO — APP Agro Peças Padrão
A2: IDENTIFICAÇÃO DO PRODUTO | F2: CUSTO DE AQUISIÇÃO (fábrica → APP) | J2: CUSTOS OPERACIONAIS | N2: CUSTO TOTAL & MARKUP | Q2: FRETE APP → CLIENTE (por região) | W2: SEGURO & PREÇO FINAL | Z2: PESQUISA DE MERCADO | AB2: EXPORTAÇÃO SHOPIFY
A3: Handle (Shopify) | B3: Título | C3: SKU | D3: Distribuidor | E3: Tipo / Categoria | F3: ⭐ Preço de Fábrica (R$) | G3: % Frete Fábrica→APP | H3: Frete Fábrica→APP (R$) | I3: ICMS Entrada (R$) | J3: % Overhead + Embalagem | K3: Overhead + Embalagem (R$) | L3: % Impostos + Comissão | M3: Impostos + Comissão (R$) | N3: Custo Total (R$) | O3: ⭐ Markup Desejado % | P3: Preço de Venda s/Frete (R$) | Q3: Frete Sul PR (R$) | R3: Frete Sul SC/RS (R$) | S3: Frete Sudeste (R$) | T3: Frete C-Oeste (R$) | U3: Frete Nordeste (R$) | V3: Frete Norte (R$) | W3: Seguro Estimado (R$) | X3: Peso Unit. (kg) | Y3: Margem Real % s/ Venda | Z3: ⭐ Preço Mín. Mercado (R$) | AA3: ⭐ Preço Máx. Mercado (R$) | AB3: Preço Shopify (Variant Price)
A4: bomba-hidraulica-valtra-valmet-62-65-68-85-86-88-78el-boi-11-e5-p-b4-11-b4-l | B4: Bomba Hidráulica Valtra-Valmet 62/65/68/85/86/88/78EL — Principal | C4: 5.0220.0547202 | D4: LIVENZA / Sohipren | E4: Bombas Hidráulicas | F4: 0 | G4: ='⚙ Configurações'!$B$17 | H4: =F4*G4 | I4: =F4*'⚙ Configurações'!$B$20 | J4: ='⚙ Configurações'!$B$4+'⚙ Configurações'!$B$5 | K4: =(F4+H4+I4)*J4 | L4: ='⚙ Configurações'!$B$6+'⚙ Configurações'!$B$7+'⚙ Configurações'!$B$8 | M4: =N4*L4/(1-L4) | N4: =F4+H4+I4+K4+M4 | O4: ='⚙ Configurações'!$B$11 | P4: =IF(O4>=1,N4*2,N4/(1-O4)) | Q4: =IF(F4=0,0,ROUND('⚙ Configurações'!$B$23+MAX(0,(6.5-3)*'⚙ Configurações'!$B$29),2)) | R4: =IF(F4=0,0,ROUND('⚙ Configurações'!$B$24+MAX(0,(6.5-3)*'⚙ Configurações'!$B$29),2)) | S4: =IF(F4=0,0,ROUND('⚙ Configurações'!$B$25+MAX(0,(6.5-3)*'⚙ Configurações'!$B$29),2)) | T4: =IF(F4=0,0,ROUND('⚙ Configurações'!$B$26+MAX(0,(6.5-3)*'⚙ Configurações'!$B$29),2)) | U4: =IF(F4=0,0,ROUND('⚙ Configurações'!$B$27+MAX(0,(6.5-3)*'⚙ Configurações'!$B$29),2)) | V4: =IF(F4=0,0,ROUND('⚙ Configurações'!$B$28+MAX(0,(6.5-3)*'⚙ Configurações'!$B$29),2)) | W4: =IF(F4=0,0,ROUND(MAX('⚙ Configurações'!$B$30,P4*'⚙ Configurações'!$B$31),2)) | X4: 6.5 | Y4: =IF(P4=0,0,(P4-N4)/P4) | Z4: 0 | AA4: 0 | AB4: =IF(P4>0,ROUND(P4,2),"")
A5: bomba-hidraulica-valtra-valmet-885-985-1280 | B5: Bomba Hidráulica Principal Valtra-Valmet 885/985/1280 | C5: 5.0220.0547201 | D5: LIVENZA / Sohipren | E5: Bombas Hidráulicas | F5: 0 | G5: ='⚙ Configurações'!$B$17 | H5: =F5*G5 | I5: =F5*'⚙ Configurações'!$B$20 | J5: ='⚙ Configurações'!$B$4+'⚙ Configurações'!$B$5 | K5: =(F5+H5+I5)*J5 | L5: ='⚙ Configurações'!$B$6+'⚙ Configurações'!$B$7+'⚙ Configurações'!$B$8 | M5: =N5*L5/(1-L5) | N5: =F5+H5+I5+K5+M5 | O5: ='⚙ Configurações'!$B$11 | P5: =IF(O5>=1,N5*2,N5/(1-O5)) | Q5: =IF(F5=0,0,ROUND('⚙ Configurações'!$B$23+MAX(0,(6.5-3)*'⚙ Configurações'!$B$29),2)) | R5: =IF(F5=0,0,ROUND('⚙ Configurações'!$B$24+MAX(0,(6.5-3)*'⚙ Configurações'!$B$29),2)) | S5: =IF(F5=0,0,ROUND('⚙ Configurações'!$B$25+MAX(0,(6.5-3)*'⚙ Configurações'!$B$29),2)) | T5: =IF(F5=0,0,ROUND('⚙ Configurações'!$B$26+MAX(0,(6.5-3)*'⚙ Configurações'!$B$29),2)) | U5: =IF(F5=0,0,ROUND('⚙ Configurações'!$B$27+MAX(0,(6.5-3)*'⚙ Configurações'!$B$29),2)) | V5: =IF(F5=0,0,ROUND('⚙ Configurações'!$B$28+MAX(0,(6.5-3)*'⚙ Configurações'!$B$29),2)) | W5: =IF(F5=0,0,ROUND(MAX('⚙ Configurações'!$B$30,P5*'⚙ Configurações'!$B$31),2)) | X5: 6.5 | Y5: =IF(P5=0,0,(P5-N5)/P5) | Z5: 0 | AA5: 0 | AB5: =IF(P5>0,ROUND(P5,2),"")
A6: bomba-hidraulica-valtra-valmet-880-980-1780 | B6: Bomba Hidráulica Principal Valtra-Valmet 880/980/1780 | C6: 5.0220.0547205 | D6: LIVENZA / Sohipren | E6: Bombas Hidráulicas | F6: 0 | G6: ='⚙ Configurações'!$B$17 | H6: =F6*G6 | I6: =F6*'⚙ Configurações'!$B$20 | J6: ='⚙ Configurações'!$B$4+'⚙ Configurações'!$B$5 | K6: =(F6+H6+I6)*J6 | L6: ='⚙ Configurações'!$B$6+'⚙ Configurações'!$B$7+'⚙ Configurações'!$B$8 | M6: =N6*L6/(1-L6) | N6: =F6+H6+I6+K6+M6 | O6: ='⚙ Configurações'!$B$11 | P6: =IF(O6>=1,N6*2,N6/(1-O6)) | Q6: =IF(F6=0,0,ROUND('⚙ Configurações'!$B$23+MAX(0,(6.5-3)*'⚙ Configurações'!$B$29),2)) | R6: =IF(F6=0,0,ROUND('⚙ Configurações'!$B$24+MAX(0,(6.5-3)*'⚙ Configurações'!$B$29),2)) | S6: =IF(F6=0,0,ROUND('⚙ Configurações'!$B$25+MAX(0,(6.5-3)*'⚙ Configurações'!$B$29),2)) | T6: =IF(F6=0,0,ROUND('⚙ Configurações'!$B$26+MAX(0,(6.5-3)*'⚙ Configurações'!$B$29),2)) | U6: =IF(F6=0,0,ROUND('⚙ Configurações'!$B$27+MAX(0,(6.5-3)*'⚙ Configurações'!$B$29),2)) | V6: =IF(F6=0,0,ROUND('⚙ Configurações'!$B$28+MAX(0,(6.5-3)*'⚙ Configurações'!$B$29),2)) | W6: =IF(F6=0,0,ROUND(MAX('⚙ Configurações'!$B$30,P6*'⚙ Configurações'!$B$31),2)) | X6: 6.5 | Y6: =IF(P6=0,0,(P6-N6)/P6) | Z6: 0 | AA6: 0 | AB6: =IF(P6>0,ROUND(P6,2),"")
A7: bomba-hidraulica-valtra-valmet-118es-128-138-148 | B7: Bomba Hidráulica Principal Valtra-Valmet 118ES/128/138/148 | C7: 5.0220.0547206 | D7: LIVENZA / Sohipren | E7: Bombas Hidráulicas | F7: 0 | G7: ='⚙ Configurações'!$B$17 | H7: =F7*G7 | I7: =F7*'⚙ Configurações'!$B$20 | J7: ='⚙ Configurações'!$B$4+'⚙ Configurações'!$B$5 | K7: =(F7+H7+I7)*J7 | L7: ='⚙ Configurações'!$B$6+'⚙ Configurações'!$B$7+'⚙ Configurações'!$B$8 | M7: =N7*L7/(1-L7) | N7: =F7+H7+I7+K7+M7 | O7: ='⚙ Configurações'!$B$11 | P7: =IF(O7>=1,N7*2,N7/(1-O7)) | Q7: =IF(F7=0,0,ROUND('⚙ Configurações'!$B$23+MAX(0,(6.5-3)*'⚙ Configurações'!$B$29),2)) | R7: =IF(F7=0,0,ROUND('⚙ Configurações'!$B$24+MAX(0,(6.5-3)*'⚙ Configurações'!$B$29),2)) | S7: =IF(F7=0,0,ROUND('⚙ Configurações'!$B$25+MAX(0,(6.5-3)*'⚙ Configurações'!$B$29),2)) | T7: =IF(F7=0,0,ROUND('⚙ Configurações'!$B$26+MAX(0,(6.5-3)*'⚙ Configurações'!$B$29),2)) | U7: =IF(F7=0,0,ROUND('⚙ Configurações'!$B$27+MAX(0,(6.5-3)*'⚙ Configurações'!$B$29),2)) | V7: =IF(F7=0,0,ROUND('⚙ Configurações'!$B$28+MAX(0,(6.5-3)*'⚙ Configurações'!$B$29),2)) | W7: =IF(F7=0,0,ROUND(MAX('⚙ Configurações'!$B$30,P7*'⚙ Configurações'!$B$31),2)) | X7: 6.5 | Y7: =IF(P7=0,0,(P7-N7)/P7) | Z7: 0 | AA7: 0 | AB7: =IF(P7>0,ROUND(P7,2),"")
A8: bomba-hidraulica-dupla-valtra-valmet-bh160 | B8: Bomba Hidráulica Dupla Valtra-Valmet BH160 | C8: 5.0220.0548824-2 | D8: LIVENZA / Sohipren | E8: Bombas Hidráulicas | F8: 0 | G8: ='⚙ Configurações'!$B$17 | H8: =F8*G8 | I8: =F8*'⚙ Configurações'!$B$20 | J8: ='⚙ Configurações'!$B$4+'⚙ Configurações'!$B$5 | K8: =(F8+H8+I8)*J8 | L8: ='⚙ Configurações'!$B$6+'⚙ Configurações'!$B$7+'⚙ Configurações'!$B$8 | M8: =N8*L8/(1-L8) | N8: =F8+H8+I8+K8+M8 | O8: ='⚙ Configurações'!$B$11 | P8: =IF(O8>=1,N8*2,N8/(1-O8)) | Q8: =IF(F8=0,0,ROUND('⚙ Configurações'!$B$23+MAX(0,(6.5-3)*'⚙ Configurações'!$B$29),2)) | R8: =IF(F8=0,0,ROUND('⚙ Configurações'!$B$24+MAX(0,(6.5-3)*'⚙ Configurações'!$B$29),2)) | S8: =IF(F8=0,0,ROUND('⚙ Configurações'!$B$25+MAX(0,(6.5-3)*'⚙ Configurações'!$B$29),2)) | T8: =IF(F8=0,0,ROUND('⚙ Configurações'!$B$26+MAX(0,(6.5-3)*'⚙ Configurações'!$B$29),2)) | U8: =IF(F8=0,0,ROUND('⚙ Configurações'!$B$27+MAX(0,(6.5-3)*'⚙ Configurações'!$B$29),2)) | V8: =IF(F8=0,0,ROUND('⚙ Configurações'!$B$28+MAX(0,(6.5-3)*'⚙ Configurações'!$B$29),2)) | W8: =IF(F8=0,0,ROUND(MAX('⚙ Configurações'!$B$30,P8*'⚙ Configurações'!$B$31),2)) | X8: 6.5 | Y8: =IF(P8=0,0,(P8-N8)/P8) | Z8: 0 | AA8: 0 | AB8: =IF(P8>0,ROUND(P8,2),"")
A9: bomba-hidraulica-massey-ferguson-mf85x-185-275-285-290-boi-5-5-c10-c10-c6-t10 | B9: Bomba Hidráulica Massey Ferguson MF85X/185/275/285/290 — Direção | C9: 5.0203.0540803 | D9: LIVENZA / Sohipren | E9: Bombas Hidráulicas | F9: 0 | G9: ='⚙ Configurações'!$B$17 | H9: =F9*G9 | I9: =F9*'⚙ Configurações'!$B$20 | J9: ='⚙ Configurações'!$B$4+'⚙ Configurações'!$B$5 | K9: =(F9+H9+I9)*J9 | L9: ='⚙ Configurações'!$B$6+'⚙ Configurações'!$B$7+'⚙ Configurações'!$B$8 | M9: =N9*L9/(1-L9) | N9: =F9+H9+I9+K9+M9 | O9: ='⚙ Configurações'!$B$11 | P9: =IF(O9>=1,N9*2,N9/(1-O9)) | Q9: =IF(F9=0,0,ROUND('⚙ Configurações'!$B$23+MAX(0,(6.5-3)*'⚙ Configurações'!$B$29),2)) | R9: =IF(F9=0,0,ROUND('⚙ Configurações'!$B$24+MAX(0,(6.5-3)*'⚙ Configurações'!$B$29),2)) | S9: =IF(F9=0,0,ROUND('⚙ Configurações'!$B$25+MAX(0,(6.5-3)*'⚙ Configurações'!$B$29),2)) | T9: =IF(F9=0,0,ROUND('⚙ Configurações'!$B$26+MAX(0,(6.5-3)*'⚙ Configurações'!$B$29),2)) | U9: =IF(F9=0,0,ROUND('⚙ Configurações'!$B$27+MAX(0,(6.5-3)*'⚙ Configurações'!$B$29),2)) | V9: =IF(F9=0,0,ROUND('⚙ Configurações'!$B$28+MAX(0,(6.5-3)*'⚙ Configurações'!$B$29),2)) | W9: =IF(F9=0,0,ROUND(MAX('⚙ Configurações'!$B$30,P9*'⚙ Configurações'!$B$31),2)) | X9: 6.5 | Y9: =IF(P9=0,0,(P9-N9)/P9) | Z9: 0 | AA9: 0 | AB9: =IF(P9>0,ROUND(P9,2),"")
A10: bomba-hidraulica-massey-ferguson-mf290-292-4x2-4x4-boi-7-b11-c11-a15-11-a42-l1 | B10: Bomba Hidráulica Massey Ferguson MF290/292 4x4 — Principal e Direção | C10: 5.0220.0547207 | D10: LIVENZA / Sohipren | E10: Bombas Hidráulicas | F10: 0 | G10: ='⚙ Configurações'!$B$17 | H10: =F10*G10 | I10: =F10*'⚙ Configurações'!$B$20 | J10: ='⚙ Configurações'!$B$4+'⚙ Configurações'!$B$5 | K10: =(F10+H10+I10)*J10 | L10: ='⚙ Configurações'!$B$6+'⚙ Configurações'!$B$7+'⚙ Configurações'!$B$8 | M10: =N10*L10/(1-L10) | N10: =F10+H10+I10+K10+M10 | O10: ='⚙ Configurações'!$B$11 | P10: =IF(O10>=1,N10*2,N10/(1-O10)) | Q10: =IF(F10=0,0,ROUND('⚙ Configurações'!$B$23+MAX(0,(6.5-3)*'⚙ Configurações'!$B$29),2)) | R10: =IF(F10=0,0,ROUND('⚙ Configurações'!$B$24+MAX(0,(6.5-3)*'⚙ Configurações'!$B$29),2)) | S10: =IF(F10=0,0,ROUND('⚙ Configurações'!$B$25+MAX(0,(6.5-3)*'⚙ Configurações'!$B$29),2)) | T10: =IF(F10=0,0,ROUND('⚙ Configurações'!$B$26+MAX(0,(6.5-3)*'⚙ Configurações'!$B$29),2)) | U10: =IF(F10=0,0,ROUND('⚙ Configurações'!$B$27+MAX(0,(6.5-3)*'⚙ Configurações'!$B$29),2)) | V10: =IF(F10=0,0,ROUND('⚙ Configurações'!$B$28+MAX(0,(6.5-3)*'⚙ Configurações'!$B$29),2)) | W10: =IF(F10=0,0,ROUND(MAX('⚙ Configurações'!$B$30,P10*'⚙ Configurações'!$B$31),2)) | X10: 6.5 | Y10: =IF(P10=0,0,(P10-N10)/P10) | Z10: 0 | AA10: 0 | AB10: =IF(P10>0,ROUND(P10,2),"")
A11: bomba-hidraulica-massey-ferguson-296-4-297-4-299-4-boi-16-b9-p5-a42-19-a42-l1 | B11: Bomba Hidráulica Massey Ferguson 296-4/297-4/299-4 — Principal | C11: 5.0220.0547216 | D11: LIVENZA / Sohipren | E11: Bombas Hidráulicas | F11: 0 | G11: ='⚙ Configurações'!$B$17 | H11: =F11*G11 | I11: =F11*'⚙ Configurações'!$B$20 | J11: ='⚙ Configurações'!$B$4+'⚙ Configurações'!$B$5 | K11: =(F11+H11+I11)*J11 | L11: ='⚙ Configurações'!$B$6+'⚙ Configurações'!$B$7+'⚙ Configurações'!$B$8 | M11: =N11*L11/(1-L11) | N11: =F11+H11+I11+K11+M11 | O11: ='⚙ Configurações'!$B$11 | P11: =IF(O11>=1,N11*2,N11/(1-O11)) | Q11: =IF(F11=0,0,ROUND('⚙ Configurações'!$B$23+MAX(0,(6.5-3)*'⚙ Configurações'!$B$29),2)) | R11: =IF(F11=0,0,ROUND('⚙ Configurações'!$B$24+MAX(0,(6.5-3)*'⚙ Configurações'!$B$29),2)) | S11: =IF(F11=0,0,ROUND('⚙ Configurações'!$B$25+MAX(0,(6.5-3)*'⚙ Configurações'!$B$29),2)) | T11: =IF(F11=0,0,ROUND('⚙ Configurações'!$B$26+MAX(0,(6.5-3)*'⚙ Configurações'!$B$29),2)) | U11: =IF(F11=0,0,ROUND('⚙ Configurações'!$B$27+MAX(0,(6.5-3)*'⚙ Configurações'!$B$29),2)) | V11: =IF(F11=0,0,ROUND('⚙ Configurações'!$B$28+MAX(0,(6.5-3)*'⚙ Configurações'!$B$29),2)) | W11: =IF(F11=0,0,ROUND(MAX('⚙ Configurações'!$B$30,P11*'⚙ Configurações'!$B$31),2)) | X11: 6.5 | Y11: =IF(P11=0,0,(P11-N11)/P11) | Z11: 0 | AA11: 0 | AB11: =IF(P11>0,ROUND(P11,2),"")
A12: bomba-hidraulica-massey-ferguson-283-290-292-l5000-boi-7-b11-c12-a-11-a-l | B12: Bomba Hidráulica Massey Ferguson 283/290/292/L5000 — Direção e Levante | C12: 5.0220.0548817 | D12: LIVENZA / Sohipren | E12: Bombas Hidráulicas | F12: 0 | G12: ='⚙ Configurações'!$B$17 | H12: =F12*G12 | I12: =F12*'⚙ Configurações'!$B$20 | J12: ='⚙ Configurações'!$B$4+'⚙ Configurações'!$B$5 | K12: =(F12+H12+I12)*J12 | L12: ='⚙ Configurações'!$B$6+'⚙ Configurações'!$B$7+'⚙ Configurações'!$B$8 | M12: =N12*L12/(1-L12) | N12: =F12+H12+I12+K12+M12 | O12: ='⚙ Configurações'!$B$11 | P12: =IF(O12>=1,N12*2,N12/(1-O12)) | Q12: =IF(F12=0,0,ROUND('⚙ Configurações'!$B$23+MAX(0,(6.5-3)*'⚙ Configurações'!$B$29),2)) | R12: =IF(F12=0,0,ROUND('⚙ Configurações'!$B$24+MAX(0,(6.5-3)*'⚙ Configurações'!$B$29),2)) | S12: =IF(F12=0,0,ROUND('⚙ Configurações'!$B$25+MAX(0,(6.5-3)*'⚙ Configurações'!$B$29),2)) | T12: =IF(F12=0,0,ROUND('⚙ Configurações'!$B$26+MAX(0,(6.5-3)*'⚙ Configurações'!$B$29),2)) | U12: =IF(F12=0,0,ROUND('⚙ Configurações'!$B$27+MAX(0,(6.5-3)*'⚙ Configurações'!$B$29),2)) | V12: =IF(F12=0,0,ROUND('⚙ Configurações'!$B$28+MAX(0,(6.5-3)*'⚙ Configurações'!$B$29),2)) | W12: =IF(F12=0,0,ROUND(MAX('⚙ Configurações'!$B$30,P12*'⚙ Configurações'!$B$31),2)) | X12: 6.5 | Y12: =IF(P12=0,0,(P12-N12)/P12) | Z12: 0 | AA12: 0 | AB12: =IF(P12>0,ROUND(P12,2),"")
A13: bomba-direcao-massey-ferguson-194-4f-362-390 | B13: Bomba de Direção Massey Ferguson 194-4F/362/365/372/390 | C13: 5.0220.0548836 | D13: LIVENZA / Sohipren | E13: Bombas Hidráulicas | F13: 0 | G13: ='⚙ Configurações'!$B$17 | H13: =F13*G13 | I13: =F13*'⚙ Configurações'!$B$20 | J13: ='⚙ Configurações'!$B$4+'⚙ Configurações'!$B$5 | K13: =(F13+H13+I13)*J13 | L13: ='⚙ Configurações'!$B$6+'⚙ Configurações'!$B$7+'⚙ Configurações'!$B$8 | M13: =N13*L13/(1-L13) | N13: =F13+H13+I13+K13+M13 | O13: ='⚙ Configurações'!$B$11 | P13: =IF(O13>=1,N13*2,N13/(1-O13)) | Q13: =IF(F13=0,0,ROUND('⚙ Configurações'!$B$23+MAX(0,(6.5-3)*'⚙ Configurações'!$B$29),2)) | R13: =IF(F13=0,0,ROUND('⚙ Configurações'!$B$24+MAX(0,(6.5-3)*'⚙ Configurações'!$B$29),2)) | S13: =IF(F13=0,0,ROUND('⚙ Configurações'!$B$25+MAX(0,(6.5-3)*'⚙ Configurações'!$B$29),2)) | T13: =IF(F13=0,0,ROUND('⚙ Configurações'!$B$26+MAX(0,(6.5-3)*'⚙ Configurações'!$B$29),2)) | U13: =IF(F13=0,0,ROUND('⚙ Configurações'!$B$27+MAX(0,(6.5-3)*'⚙ Configurações'!$B$29),2)) | V13: =IF(F13=0,0,ROUND('⚙ Configurações'!$B$28+MAX(0,(6.5-3)*'⚙ Configurações'!$B$29),2)) | W13: =IF(F13=0,0,ROUND(MAX('⚙ Configurações'!$B$30,P13*'⚙ Configurações'!$B$31),2)) | X13: 6.5 | Y13: =IF(P13=0,0,(P13-N13)/P13) | Z13: 0 | AA13: 0 | AB13: =IF(P13>0,ROUND(P13,2),"")
A14: bomba-hidraulica-massey-ferguson-mf-a013 | B14: Bomba Hidráulica Massey Ferguson MF A-013 — Direção e Levante 3000/6000 | C14: 5.1302.0547820 | D14: LIVENZA / Sohipren | E14: Bombas Hidráulicas | F14: 0 | G14: ='⚙ Configurações'!$B$17 | H14: =F14*G14 | I14: =F14*'⚙ Configurações'!$B$20 | J14: ='⚙ Configurações'!$B$4+'⚙ Configurações'!$B$5 | K14: =(F14+H14+I14)*J14 | L14: ='⚙ Configurações'!$B$6+'⚙ Configurações'!$B$7+'⚙ Configurações'!$B$8 | M14: =N14*L14/(1-L14) | N14: =F14+H14+I14+K14+M14 | O14: ='⚙ Configurações'!$B$11 | P14: =IF(O14>=1,N14*2,N14/(1-O14)) | Q14: =IF(F14=0,0,ROUND('⚙ Configurações'!$B$23+MAX(0,(6.5-3)*'⚙ Configurações'!$B$29),2)) | R14: =IF(F14=0,0,ROUND('⚙ Configurações'!$B$24+MAX(0,(6.5-3)*'⚙ Configurações'!$B$29),2)) | S14: =IF(F14=0,0,ROUND('⚙ Configurações'!$B$25+MAX(0,(6.5-3)*'⚙ Configurações'!$B$29),2)) | T14: =IF(F14=0,0,ROUND('⚙ Configurações'!$B$26+MAX(0,(6.5-3)*'⚙ Configurações'!$B$29),2)) | U14: =IF(F14=0,0,ROUND('⚙ Configurações'!$B$27+MAX(0,(6.5-3)*'⚙ Configurações'!$B$29),2)) | V14: =IF(F14=0,0,ROUND('⚙ Configurações'!$B$28+MAX(0,(6.5-3)*'⚙ Configurações'!$B$29),2)) | W14: =IF(F14=0,0,ROUND(MAX('⚙ Configurações'!$B$30,P14*'⚙ Configurações'!$B$31),2)) | X14: 6.5 | Y14: =IF(P14=0,0,(P14-N14)/P14) | Z14: 0 | AA14: 0 | AB14: =IF(P14>0,ROUND(P14,2),"")
A15: bomba-hidraulica-massey-ferguson-mf-a004-4215-4255 | B15: Bomba Hidráulica Massey Ferguson MF A-004 — 4215/4220/4235/4255 | C15: 5.1302.0547844 | D15: LIVENZA / Sohipren | E15: Bombas Hidráulicas | F15: 0 | G15: ='⚙ Configurações'!$B$17 | H15: =F15*G15 | I15: =F15*'⚙ Configurações'!$B$20 | J15: ='⚙ Configurações'!$B$4+'⚙ Configurações'!$B$5 | K15: =(F15+H15+I15)*J15 | L15: ='⚙ Configurações'!$B$6+'⚙ Configurações'!$B$7+'⚙ Configurações'!$B$8 | M15: =N15*L15/(1-L15) | N15: =F15+H15+I15+K15+M15 | O15: ='⚙ Configurações'!$B$11 | P15: =IF(O15>=1,N15*2,N15/(1-O15)) | Q15: =IF(F15=0,0,ROUND('⚙ Configurações'!$B$23+MAX(0,(6.5-3)*'⚙ Configurações'!$B$29),2)) | R15: =IF(F15=0,0,ROUND('⚙ Configurações'!$B$24+MAX(0,(6.5-3)*'⚙ Configurações'!$B$29),2)) | S15: =IF(F15=0,0,ROUND('⚙ Configurações'!$B$25+MAX(0,(6.5-3)*'⚙ Configurações'!$B$29),2)) | T15: =IF(F15=0,0,ROUND('⚙ Configurações'!$B$26+MAX(0,(6.5-3)*'⚙ Configurações'!$B$29),2)) | U15: =IF(F15=0,0,ROUND('⚙ Configurações'!$B$27+MAX(0,(6.5-3)*'⚙ Configurações'!$B$29),2)) | V15: =IF(F15=0,0,ROUND('⚙ Configurações'!$B$28+MAX(0,(6.5-3)*'⚙ Configurações'!$B$29),2)) | W15: =IF(F15=0,0,ROUND(MAX('⚙ Configurações'!$B$30,P15*'⚙ Configurações'!$B$31),2)) | X15: 6.5 | Y15: =IF(P15=0,0,(P15-N15)/P15) | Z15: 0 | AA15: 0 | AB15: =IF(P15>0,ROUND(P15,2),"")
... A27: bomba-hidraulica-john-deere-colhedeira-1150-1165-1185-7300-7500-8500-boi-11-b9-p4-a42 | B27: Bomba Hidráulica John Deere Colhedeira 1150/1165/1185/7300/7500/8500 | C27: 5.0209.0547219 | D27: LIVENZA / Sohipren | E27: Bombas Hidráulicas | F27: 0 | G27: ='⚙ Configurações'!$B$17 | H27: =F27*G27 | I27: =F27*'⚙ Configurações'!$B$20 | J27: ='⚙ Configurações'!$B$4+'⚙ Configurações'!$B$5 | K27: =(F27+H27+I27)*J27 | L27: ='⚙ Configurações'!$B$6+'⚙ Configurações'!$B$7+'⚙ Configurações'!$B$8 | M27: =N27*L27/(1-L27) | N27: =F27+H27+I27+K27+M27 | O27: ='⚙ Configurações'!$B$11 | P27: =IF(O27>=1,N27*2,N27/(1-O27)) | Q27: =IF(F27=0,0,ROUND('⚙ Configurações'!$B$23+MAX(0,(6.5-3)*'⚙ Configurações'!$B$29),2)) | R27: =IF(F27=0,0,ROUND('⚙ Configurações'!$B$24+MAX(0,(6.5-3)*'⚙ Configurações'!$B$29),2)) | S27: =IF(F27=0,0,ROUND('⚙ Configurações'!$B$25+MAX(0,(6.5-3)*'⚙ Configurações'!$B$29),2)) | T27: =IF(F27=0,0,ROUND('⚙ Configurações'!$B$26+MAX(0,(6.5-3)*'⚙ Configurações'!$B$29),2)) | U27: =IF(F27=0,0,ROUND('⚙ Configurações'!$B$27+MAX(0,(6.5-3)*'⚙ Configurações'!$B$29),2)) | V27: =IF(F27=0,0,ROUND('⚙ Configurações'!$B$28+MAX(0,(6.5-3)*'⚙ Configurações'!$B$29),2)) | W27: =IF(F27=0,0,ROUND(MAX('⚙ Configurações'!$B$30,P27*'⚙ Configurações'!$B$31),2)) | X27: 6.5 | Y27: =IF(P27=0,0,(P27-N27)/P27) | Z27: 0 | AA27: 0 | AB27: =IF(P27>0,ROUND(P27,2),"")
A28: sensor-fluxo-sflx2-agral | B28: Sensor de Fluxo SFLX2 — Agral | Plantadeiras de Precisão | C28: SFLX2 | D28: Agral (ADG) | E28: Sensores Agrícolas | F28: 0 | G28: ='⚙ Configurações'!$B$19 | H28: =F28*G28 | I28: =F28*'⚙ Configurações'!$B$20 | J28: ='⚙ Configurações'!$B$4+'⚙ Configurações'!$B$5 | K28: =(F28+H28+I28)*J28 | L28: ='⚙ Configurações'!$B$6+'⚙ Configurações'!$B$7+'⚙ Configurações'!$B$8 | M28: =N28*L28/(1-L28) | N28: =F28+H28+I28+K28+M28 | O28: ='⚙ Configurações'!$B$12 | P28: =IF(O28>=1,N28*2,N28/(1-O28)) | Q28: =IF(F28=0,0,ROUND('⚙ Configurações'!$B$23+MAX(0,(0.3-3)*'⚙ Configurações'!$B$29),2)) | R28: =IF(F28=0,0,ROUND('⚙ Configurações'!$B$24+MAX(0,(0.3-3)*'⚙ Configurações'!$B$29),2)) | S28: =IF(F28=0,0,ROUND('⚙ Configurações'!$B$25+MAX(0,(0.3-3)*'⚙ Configurações'!$B$29),2)) | T28: =IF(F28=0,0,ROUND('⚙ Configurações'!$B$26+MAX(0,(0.3-3)*'⚙ Configurações'!$B$29),2)) | U28: =IF(F28=0,0,ROUND('⚙ Configurações'!$B$27+MAX(0,(0.3-3)*'⚙ Configurações'!$B$29),2)) | V28: =IF(F28=0,0,ROUND('⚙ Configurações'!$B$28+MAX(0,(0.3-3)*'⚙ Configurações'!$B$29),2)) | W28: =IF(F28=0,0,ROUND(MAX('⚙ Configurações'!$B$30,P28*'⚙ Configurações'!$B$31),2)) | X28: 0.3 | Y28: =IF(P28=0,0,(P28-N28)/P28) | Z28: 0 | AA28: 0 | AB28: =IF(P28>0,ROUND(P28,2),"")
A29: sensor-semente-pul2-agral | B29: Sensor de Semente PUL-2 — Agral | Plantadeiras de Precisão | C29: PUL-2 | D29: Agral (ADG) | E29: Sensores Agrícolas | F29: 0 | G29: ='⚙ Configurações'!$B$19 | H29: =F29*G29 | I29: =F29*'⚙ Configurações'!$B$20 | J29: ='⚙ Configurações'!$B$4+'⚙ Configurações'!$B$5 | K29: =(F29+H29+I29)*J29 | L29: ='⚙ Configurações'!$B$6+'⚙ Configurações'!$B$7+'⚙ Configurações'!$B$8 | M29: =N29*L29/(1-L29) | N29: =F29+H29+I29+K29+M29 | O29: ='⚙ Configurações'!$B$12 | P29: =IF(O29>=1,N29*2,N29/(1-O29)) | Q29: =IF(F29=0,0,ROUND('⚙ Configurações'!$B$23+MAX(0,(0.3-3)*'⚙ Configurações'!$B$29),2)) | R29: =IF(F29=0,0,ROUND('⚙ Configurações'!$B$24+MAX(0,(0.3-3)*'⚙ Configurações'!$B$29),2)) | S29: =IF(F29=0,0,ROUND('⚙ Configurações'!$B$25+MAX(0,(0.3-3)*'⚙ Configurações'!$B$29),2)) | T29: =IF(F29=0,0,ROUND('⚙ Configurações'!$B$26+MAX(0,(0.3-3)*'⚙ Configurações'!$B$29),2)) | U29: =IF(F29=0,0,ROUND('⚙ Configurações'!$B$27+MAX(0,(0.3-3)*'⚙ Configurações'!$B$29),2)) | V29: =IF(F29=0,0,ROUND('⚙ Configurações'!$B$28+MAX(0,(0.3-3)*'⚙ Configurações'!$B$29),2)) | W29: =IF(F29=0,0,ROUND(MAX('⚙ Configurações'!$B$30,P29*'⚙ Configurações'!$B$31),2)) | X29: 0.3 | Y29: =IF(P29=0,0,(P29-N29)/P29) | Z29: 0 | AA29: 0 | AB29: =IF(P29>0,ROUND(P29,2),"")
A30: gps-agricola-gr200-greco-agro-tech-navegacao-de-precisao | B30: GPS Agrícola GR200 — Greco Agro Tech | Navegação de Precisão | C30: GR141207 | D30: Greco Agro Tech | E30: GPS Agrícola | F30: 0 | G30: ='⚙ Configurações'!$B$18 | H30: =F30*G30 | I30: =F30*'⚙ Configurações'!$B$20 | J30: ='⚙ Configurações'!$B$4+'⚙ Configurações'!$B$5 | K30: =(F30+H30+I30)*J30 | L30: ='⚙ Configurações'!$B$6+'⚙ Configurações'!$B$7+'⚙ Configurações'!$B$8 | M30: =N30*L30/(1-L30) | N30: =F30+H30+I30+K30+M30 | O30: ='⚙ Configurações'!$B$12 | P30: =IF(O30>=1,N30*2,N30/(1-O30)) | Q30: =IF(F30=0,0,ROUND('⚙ Configurações'!$B$23+MAX(0,(0.8-3)*'⚙ Configurações'!$B$29),2)) | R30: =IF(F30=0,0,ROUND('⚙ Configurações'!$B$24+MAX(0,(0.8-3)*'⚙ Configurações'!$B$29),2)) | S30: =IF(F30=0,0,ROUND('⚙ Configurações'!$B$25+MAX(0,(0.8-3)*'⚙ Configurações'!$B$29),2)) | T30: =IF(F30=0,0,ROUND('⚙ Configurações'!$B$26+MAX(0,(0.8-3)*'⚙ Configurações'!$B$29),2)) | U30: =IF(F30=0,0,ROUND('⚙ Configurações'!$B$27+MAX(0,(0.8-3)*'⚙ Configurações'!$B$29),2)) | V30: =IF(F30=0,0,ROUND('⚙ Configurações'!$B$28+MAX(0,(0.8-3)*'⚙ Configurações'!$B$29),2)) | W30: =IF(F30=0,0,ROUND(MAX('⚙ Configurações'!$B$30,P30*'⚙ Configurações'!$B$31),2)) | X30: 0.8 | Y30: =IF(P30=0,0,(P30-N30)/P30) | Z30: 0 | AA30: 0 | AB30: =IF(P30>0,ROUND(P30,2),"")
A31: kit-de-iluminacao-noturna-pulverizacao-greco-agro-tech | B31: Kit de Iluminação Noturna Pulverização — Greco Agro Tech | C31: GR141165 | D31: Greco Agro Tech | E31: Iluminação Agrícola | F31: 0 | G31: ='⚙ Configurações'!$B$18 | H31: =F31*G31 | I31: =F31*'⚙ Configurações'!$B$20 | J31: ='⚙ Configurações'!$B$4+'⚙ Configurações'!$B$5 | K31: =(F31+H31+I31)*J31 | L31: ='⚙ Configurações'!$B$6+'⚙ Configurações'!$B$7+'⚙ Configurações'!$B$8 | M31: =N31*L31/(1-L31) | N31: =F31+H31+I31+K31+M31 | O31: ='⚙ Configurações'!$B$12 | P31: =IF(O31>=1,N31*2,N31/(1-O31)) | Q31: =IF(F31=0,0,ROUND('⚙ Configurações'!$B$23+MAX(0,(0.5-3)*'⚙ Configurações'!$B$29),2)) | R31: =IF(F31=0,0,ROUND('⚙ Configurações'!$B$24+MAX(0,(0.5-3)*'⚙ Configurações'!$B$29),2)) | S31: =IF(F31=0,0,ROUND('⚙ Configurações'!$B$25+MAX(0,(0.5-3)*'⚙ Configurações'!$B$29),2)) | T31: =IF(F31=0,0,ROUND('⚙ Configurações'!$B$26+MAX(0,(0.5-3)*'⚙ Configurações'!$B$29),2)) | U31: =IF(F31=0,0,ROUND('⚙ Configurações'!$B$27+MAX(0,(0.5-3)*'⚙ Configurações'!$B$29),2)) | V31: =IF(F31=0,0,ROUND('⚙ Configurações'!$B$28+MAX(0,(0.5-3)*'⚙ Configurações'!$B$29),2)) | W31: =IF(F31=0,0,ROUND(MAX('⚙ Configurações'!$B$30,P31*'⚙ Configurações'!$B$31),2)) | X31: 0.5 | Y31: =IF(P31=0,0,(P31-N31)/P31) | Z31: 0 | AA31: 0 | AB31: =IF(P31>0,ROUND(P31,2),"")
A32: kit-ponta-de-cerca-greco-agro-tech | B32: Kit Ponta de Cerca — Greco Agro Tech | C32: GR140990-30M | D32: Greco Agro Tech | E32: Kits Agrícolas | F32: 0 | G32: ='⚙ Configurações'!$B$18 | H32: =F32*G32 | I32: =F32*'⚙ Configurações'!$B$20 | J32: ='⚙ Configurações'!$B$4+'⚙ Configurações'!$B$5 | K32: =(F32+H32+I32)*J32 | L32: ='⚙ Configurações'!$B$6+'⚙ Configurações'!$B$7+'⚙ Configurações'!$B$8 | M32: =N32*L32/(1-L32) | N32: =F32+H32+I32+K32+M32 | O32: ='⚙ Configurações'!$B$12 | P32: =IF(O32>=1,N32*2,N32/(1-O32)) | Q32: =IF(F32=0,0,ROUND('⚙ Configurações'!$B$23+MAX(0,(0.4-3)*'⚙ Configurações'!$B$29),2)) | R32: =IF(F32=0,0,ROUND('⚙ Configurações'!$B$24+MAX(0,(0.4-3)*'⚙ Configurações'!$B$29),2)) | S32: =IF(F32=0,0,ROUND('⚙ Configurações'!$B$25+MAX(0,(0.4-3)*'⚙ Configurações'!$B$29),2)) | T32: =IF(F32=0,0,ROUND('⚙ Configurações'!$B$26+MAX(0,(0.4-3)*'⚙ Configurações'!$B$29),2)) | U32: =IF(F32=0,0,ROUND('⚙ Configurações'!$B$27+MAX(0,(0.4-3)*'⚙ Configurações'!$B$29),2)) | V32: =IF(F32=0,0,ROUND('⚙ Configurações'!$B$28+MAX(0,(0.4-3)*'⚙ Configurações'!$B$29),2)) | W32: =IF(F32=0,0,ROUND(MAX('⚙ Configurações'!$B$30,P32*'⚙ Configurações'!$B$31),2)) | X32: 0.4 | Y32: =IF(P32=0,0,(P32-N32)/P32) | Z32: 0 | AA32: 0 | AB32: =IF(P32>0,ROUND(P32,2),"")
A33: sensor-de-levante-haste-greco-agro-tech-precision-planting-pm400 | B33: Sensor de Levante Haste — Greco Agro Tech | Precision Planting PM400 | C33: GR140682 | D33: Agral (ADG) | E33: Sensores Agrícolas | F33: 0 | G33: ='⚙ Configurações'!$B$19 | H33: =F33*G33 | I33: =F33*'⚙ Configurações'!$B$20 | J33: ='⚙ Configurações'!$B$4+'⚙ Configurações'!$B$5 | K33: =(F33+H33+I33)*J33 | L33: ='⚙ Configurações'!$B$6+'⚙ Configurações'!$B$7+'⚙ Configurações'!$B$8 | M33: =N33*L33/(1-L33) | N33: =F33+H33+I33+K33+M33 | O33: ='⚙ Configurações'!$B$12 | P33: =IF(O33>=1,N33*2,N33/(1-O33)) | Q33: =IF(F33=0,0,ROUND('⚙ Configurações'!$B$23+MAX(0,(0.3-3)*'⚙ Configurações'!$B$29),2)) | R33: =IF(F33=0,0,ROUND('⚙ Configurações'!$B$24+MAX(0,(0.3-3)*'⚙ Configurações'!$B$29),2)) | S33: =IF(F33=0,0,ROUND('⚙ Configurações'!$B$25+MAX(0,(0.3-3)*'⚙ Configurações'!$B$29),2)) | T33: =IF(F33=0,0,ROUND('⚙ Configurações'!$B$26+MAX(0,(0.3-3)*'⚙ Configurações'!$B$29),2)) | U33: =IF(F33=0,0,ROUND('⚙ Configurações'!$B$27+MAX(0,(0.3-3)*'⚙ Configurações'!$B$29),2)) | V33: =IF(F33=0,0,ROUND('⚙ Configurações'!$B$28+MAX(0,(0.3-3)*'⚙ Configurações'!$B$29),2)) | W33: =IF(F33=0,0,ROUND(MAX('⚙ Configurações'!$B$30,P33*'⚙ Configurações'!$B$31),2)) | X33: 0.3 | Y33: =IF(P33=0,0,(P33-N33)/P33) | Z33: 0 | AA33: 0 | AB33: =IF(P33>0,ROUND(P33,2),"")
A34: sensor-de-levante-corrente-greco-agro-tech-precision-planting-pm400 | B34: Sensor de Levante Corrente — Greco Agro Tech | Precision Planting PM400 | C34: GR140012 | D34: Agral (ADG) | E34: Sensores Agrícolas | F34: 0 | G34: ='⚙ Configurações'!$B$19 | H34: =F34*G34 | I34: =F34*'⚙ Configurações'!$B$20 | J34: ='⚙ Configurações'!$B$4+'⚙ Configurações'!$B$5 | K34: =(F34+H34+I34)*J34 | L34: ='⚙ Configurações'!$B$6+'⚙ Configurações'!$B$7+'⚙ Configurações'!$B$8 | M34: =N34*L34/(1-L34) | N34: =F34+H34+I34+K34+M34 | O34: ='⚙ Configurações'!$B$12 | P34: =IF(O34>=1,N34*2,N34/(1-O34)) | Q34: =IF(F34=0,0,ROUND('⚙ Configurações'!$B$23+MAX(0,(0.3-3)*'⚙ Configurações'!$B$29),2)) | R34: =IF(F34=0,0,ROUND('⚙ Configurações'!$B$24+MAX(0,(0.3-3)*'⚙ Configurações'!$B$29),2)) | S34: =IF(F34=0,0,ROUND('⚙ Configurações'!$B$25+MAX(0,(0.3-3)*'⚙ Configurações'!$B$29),2)) | T34: =IF(F34=0,0,ROUND('⚙ Configurações'!$B$26+MAX(0,(0.3-3)*'⚙ Configurações'!$B$29),2)) | U34: =IF(F34=0,0,ROUND('⚙ Configurações'!$B$27+MAX(0,(0.3-3)*'⚙ Configurações'!$B$29),2)) | V34: =IF(F34=0,0,ROUND('⚙ Configurações'!$B$28+MAX(0,(0.3-3)*'⚙ Configurações'!$B$29),2)) | W34: =IF(F34=0,0,ROUND(MAX('⚙ Configurações'!$B$30,P34*'⚙ Configurações'!$B$31),2)) | X34: 0.3 | Y34: =IF(P34=0,0,(P34-N34)/P34) | Z34: 0 | AA34: 0 | AB34: =IF(P34>0,ROUND(P34,2),"")
A35: monitor-de-fluxo-de-sementes-gr500-greco-agro-tech | B35: Monitor de Fluxo de Sementes GR500 — Greco Agro Tech | C35: GR142398 | D35: Greco Agro Tech | E35: Monitores Agrícolas | F35: 0 | G35: ='⚙ Configurações'!$B$18 | H35: =F35*G35 | I35: =F35*'⚙ Configurações'!$B$20 | J35: ='⚙ Configurações'!$B$4+'⚙ Configurações'!$B$5 | K35: =(F35+H35+I35)*J35 | L35: ='⚙ Configurações'!$B$6+'⚙ Configurações'!$B$7+'⚙ Configurações'!$B$8 | M35: =N35*L35/(1-L35) | N35: =F35+H35+I35+K35+M35 | O35: ='⚙ Configurações'!$B$12 | P35: =IF(O35>=1,N35*2,N35/(1-O35)) | Q35: =IF(F35=0,0,ROUND('⚙ Configurações'!$B$23+MAX(0,(1.2-3)*'⚙ Configurações'!$B$29),2)) | R35: =IF(F35=0,0,ROUND('⚙ Configurações'!$B$24+MAX(0,(1.2-3)*'⚙ Configurações'!$B$29),2)) | S35: =IF(F35=0,0,ROUND('⚙ Configurações'!$B$25+MAX(0,(1.2-3)*'⚙ Configurações'!$B$29),2)) | T35: =IF(F35=0,0,ROUND('⚙ Configurações'!$B$26+MAX(0,(1.2-3)*'⚙ Configurações'!$B$29),2)) | U35: =IF(F35=0,0,ROUND('⚙ Configurações'!$B$27+MAX(0,(1.2-3)*'⚙ Configurações'!$B$29),2)) | V35: =IF(F35=0,0,ROUND('⚙ Configurações'!$B$28+MAX(0,(1.2-3)*'⚙ Configurações'!$B$29),2)) | W35: =IF(F35=0,0,ROUND(MAX('⚙ Configurações'!$B$30,P35*'⚙ Configurações'!$B$31),2)) | X35: 1.2 | Y35: =IF(P35=0,0,(P35-N35)/P35) | Z35: 0 | AA35: 0 | AB35: =IF(P35>0,ROUND(P35,2),"")
A36: sensor-de-fluxo-25-4mm-greco-agro-tech-precision-planting-pm400 | B36: Sensor de Fluxo 25,4mm — Greco Agro Tech | Precision Planting PM400 | C36: GR142226 | D36: Agral (ADG) | E36: Sensores Agrícolas | F36: 0 | G36: ='⚙ Configurações'!$B$19 | H36: =F36*G36 | I36: =F36*'⚙ Configurações'!$B$20 | J36: ='⚙ Configurações'!$B$4+'⚙ Configurações'!$B$5 | K36: =(F36+H36+I36)*J36 | L36: ='⚙ Configurações'!$B$6+'⚙ Configurações'!$B$7+'⚙ Configurações'!$B$8 | M36: =N36*L36/(1-L36) | N36: =F36+H36+I36+K36+M36 | O36: ='⚙ Configurações'!$B$12 | P36: =IF(O36>=1,N36*2,N36/(1-O36)) | Q36: =IF(F36=0,0,ROUND('⚙ Configurações'!$B$23+MAX(0,(0.3-3)*'⚙ Configurações'!$B$29),2)) | R36: =IF(F36=0,0,ROUND('⚙ Configurações'!$B$24+MAX(0,(0.3-3)*'⚙ Configurações'!$B$29),2)) | S36: =IF(F36=0,0,ROUND('⚙ Configurações'!$B$25+MAX(0,(0.3-3)*'⚙ Configurações'!$B$29),2)) | T36: =IF(F36=0,0,ROUND('⚙ Configurações'!$B$26+MAX(0,(0.3-3)*'⚙ Configurações'!$B$29),2)) | U36: =IF(F36=0,0,ROUND('⚙ Configurações'!$B$27+MAX(0,(0.3-3)*'⚙ Configurações'!$B$29),2)) | V36: =IF(F36=0,0,ROUND('⚙ Configurações'!$B$28+MAX(0,(0.3-3)*'⚙ Configurações'!$B$29),2)) | W36: =IF(F36=0,0,ROUND(MAX('⚙ Configurações'!$B$30,P36*'⚙ Configurações'!$B$31),2)) | X36: 0.3 | Y36: =IF(P36=0,0,(P36-N36)/P36) | Z36: 0 | AA36: 0 | AB36: =IF(P36>0,ROUND(P36,2),"")
A37: sensor-de-fluxo-32mm-greco-agro-tech-precision-planting-pm400 | B37: Sensor de Fluxo 32mm — Greco Agro Tech | Precision Planting PM400 | C37: GR142227 | D37: Agral (ADG) | E37: Sensores Agrícolas | F37: 0 | G37: ='⚙ Configurações'!$B$19 | H37: =F37*G37 | I37: =F37*'⚙ Configurações'!$B$20 | J37: ='⚙ Configurações'!$B$4+'⚙ Configurações'!$B$5 | K37: =(F37+H37+I37)*J37 | L37: ='⚙ Configurações'!$B$6+'⚙ Configurações'!$B$7+'⚙ Configurações'!$B$8 | M37: =N37*L37/(1-L37) | N37: =F37+H37+I37+K37+M37 | O37: ='⚙ Configurações'!$B$12 | P37: =IF(O37>=1,N37*2,N37/(1-O37)) | Q37: =IF(F37=0,0,ROUND('⚙ Configurações'!$B$23+MAX(0,(0.3-3)*'⚙ Configurações'!$B$29),2)) | R37: =IF(F37=0,0,ROUND('⚙ Configurações'!$B$24+MAX(0,(0.3-3)*'⚙ Configurações'!$B$29),2)) | S37: =IF(F37=0,0,ROUND('⚙ Configurações'!$B$25+MAX(0,(0.3-3)*'⚙ Configurações'!$B$29),2)) | T37: =IF(F37=0,0,ROUND('⚙ Configurações'!$B$26+MAX(0,(0.3-3)*'⚙ Configurações'!$B$29),2)) | U37: =IF(F37=0,0,ROUND('⚙ Configurações'!$B$27+MAX(0,(0.3-3)*'⚙ Configurações'!$B$29),2)) | V37: =IF(F37=0,0,ROUND('⚙ Configurações'!$B$28+MAX(0,(0.3-3)*'⚙ Configurações'!$B$29),2)) | W37: =IF(F37=0,0,ROUND(MAX('⚙ Configurações'!$B$30,P37*'⚙ Configurações'!$B$31),2)) | X37: 0.3 | Y37: =IF(P37=0,0,(P37-N37)/P37) | Z37: 0 | AA37: 0 | AB37: =IF(P37>0,ROUND(P37,2),"")
A38: sensor-de-fluxo-50-8mm-greco-agro-tech-precision-planting-pm400 | B38: Sensor de Fluxo 50,8mm — Greco Agro Tech | Precision Planting PM400 | C38: GR142228 | D38: Agral (ADG) | E38: Sensores Agrícolas | F38: 0 | G38: ='⚙ Configurações'!$B$19 | H38: =F38*G38 | I38: =F38*'⚙ Configurações'!$B$20 | J38: ='⚙ Configurações'!$B$4+'⚙ Configurações'!$B$5 | K38: =(F38+H38+I38)*J38 | L38: ='⚙ Configurações'!$B$6+'⚙ Configurações'!$B$7+'⚙ Configurações'!$B$8 | M38: =N38*L38/(1-L38) | N38: =F38+H38+I38+K38+M38 | O38: ='⚙ Configurações'!$B$12 | P38: =IF(O38>=1,N38*2,N38/(1-O38)) | Q38: =IF(F38=0,0,ROUND('⚙ Configurações'!$B$23+MAX(0,(0.3-3)*'⚙ Configurações'!$B$29),2)) | R38: =IF(F38=0,0,ROUND('⚙ Configurações'!$B$24+MAX(0,(0.3-3)*'⚙ Configurações'!$B$29),2)) | S38: =IF(F38=0,0,ROUND('⚙ Configurações'!$B$25+MAX(0,(0.3-3)*'⚙ Configurações'!$B$29),2)) | T38: =IF(F38=0,0,ROUND('⚙ Configurações'!$B$26+MAX(0,(0.3-3)*'⚙ Configurações'!$B$29),2)) | U38: =IF(F38=0,0,ROUND('⚙ Configurações'!$B$27+MAX(0,(0.3-3)*'⚙ Configurações'!$B$29),2)) | V38: =IF(F38=0,0,ROUND('⚙ Configurações'!$B$28+MAX(0,(0.3-3)*'⚙ Configurações'!$B$29),2)) | W38: =IF(F38=0,0,ROUND(MAX('⚙ Configurações'!$B$30,P38*'⚙ Configurações'!$B$31),2)) | X38: 0.3 | Y38: =IF(P38=0,0,(P38-N38)/P38) | Z38: 0 | AA38: 0 | AB38: =IF(P38>0,ROUND(P38,2),"")
A39: sensor-de-semente-greco-agro-tech-precision-planting-pm400 | B39: Sensor de Semente — Greco Agro Tech | Precision Planting PM400 | C39: GR142229 | D39: Agral (ADG) | E39: Sensores Agrícolas | F39: 0 | G39: ='⚙ Configurações'!$B$19 | H39: =F39*G39 | I39: =F39*'⚙ Configurações'!$B$20 | J39: ='⚙ Configurações'!$B$4+'⚙ Configurações'!$B$5 | K39: =(F39+H39+I39)*J39 | L39: ='⚙ Configurações'!$B$6+'⚙ Configurações'!$B$7+'⚙ Configurações'!$B$8 | M39: =N39*L39/(1-L39) | N39: =F39+H39+I39+K39+M39 | O39: ='⚙ Configurações'!$B$12 | P39: =IF(O39>=1,N39*2,N39/(1-O39)) | Q39: =IF(F39=0,0,ROUND('⚙ Configurações'!$B$23+MAX(0,(0.3-3)*'⚙ Configurações'!$B$29),2)) | R39: =IF(F39=0,0,ROUND('⚙ Configurações'!$B$24+MAX(0,(0.3-3)*'⚙ Configurações'!$B$29),2)) | S39: =IF(F39=0,0,ROUND('⚙ Configurações'!$B$25+MAX(0,(0.3-3)*'⚙ Configurações'!$B$29),2)) | T39: =IF(F39=0,0,ROUND('⚙ Configurações'!$B$26+MAX(0,(0.3-3)*'⚙ Configurações'!$B$29),2)) | U39: =IF(F39=0,0,ROUND('⚙ Configurações'!$B$27+MAX(0,(0.3-3)*'⚙ Configurações'!$B$29),2)) | V39: =IF(F39=0,0,ROUND('⚙ Configurações'!$B$28+MAX(0,(0.3-3)*'⚙ Configurações'!$B$29),2)) | W39: =IF(F39=0,0,ROUND(MAX('⚙ Configurações'!$B$30,P39*'⚙ Configurações'!$B$31),2)) | X39: 0.3 | Y39: =IF(P39=0,0,(P39-N39)/P39) | Z39: 0 | AA39: 0 | AB39: =IF(P39>0,ROUND(P39,2),"")
A40: suporte-do-dosador-agco-acx3266690-plantadeira-momentum | B40: Suporte do Dosador — AGCO ACX3266690 | Plantadeira Momentum | C40: ACX3266690 | D40: AGCO (ADG) | E40: Peças para Plantadeira | F40: 0 | G40: ='⚙ Configurações'!$B$19 | H40: =F40*G40 | I40: =F40*'⚙ Configurações'!$B$20 | J40: ='⚙ Configurações'!$B$4+'⚙ Configurações'!$B$5 | K40: =(F40+H40+I40)*J40 | L40: ='⚙ Configurações'!$B$6+'⚙ Configurações'!$B$7+'⚙ Configurações'!$B$8 | M40: =N40*L40/(1-L40) | N40: =F40+H40+I40+K40+M40 | O40: ='⚙ Configurações'!$B$13 | P40: =IF(O40>=1,N40*2,N40/(1-O40)) | Q40: =IF(F40=0,0,ROUND('⚙ Configurações'!$B$23+MAX(0,(0.2-3)*'⚙ Configurações'!$B$29),2)) | R40: =IF(F40=0,0,ROUND('⚙ Configurações'!$B$24+MAX(0,(0.2-3)*'⚙ Configurações'!$B$29),2)) | S40: =IF(F40=0,0,ROUND('⚙ Configurações'!$B$25+MAX(0,(0.2-3)*'⚙ Configurações'!$B$29),2)) | T40: =IF(F40=0,0,ROUND('⚙ Configurações'!$B$26+MAX(0,(0.2-3)*'⚙ Configurações'!$B$29),2)) | U40: =IF(F40=0,0,ROUND('⚙ Configurações'!$B$27+MAX(0,(0.2-3)*'⚙ Configurações'!$B$29),2)) | V40: =IF(F40=0,0,ROUND('⚙ Configurações'!$B$28+MAX(0,(0.2-3)*'⚙ Configurações'!$B$29),2)) | W40: =IF(F40=0,0,ROUND(MAX('⚙ Configurações'!$B$30,P40*'⚙ Configurações'!$B$31),2)) | X40: 0.2 | Y40: =IF(P40=0,0,(P40-N40)/P40) | Z40: 0 | AA40: 0 | AB40: =IF(P40>0,ROUND(P40,2),"")
A41: conjunto-montado-reservatorio-de-sementes-mecanico-agco-acx3454710 | B41: Conjunto Montado Reservatório de Sementes Mecânico — AGCO ACX3454710 | C41: ACX3454710 | D41: AGCO (ADG) | E41: Peças para Plantadeira | F41: 0 | G41: ='⚙ Configurações'!$B$19 | H41: =F41*G41 | I41: =F41*'⚙ Configurações'!$B$20 | J41: ='⚙ Configurações'!$B$4+'⚙ Configurações'!$B$5 | K41: =(F41+H41+I41)*J41 | L41: ='⚙ Configurações'!$B$6+'⚙ Configurações'!$B$7+'⚙ Configurações'!$B$8 | M41: =N41*L41/(1-L41) | N41: =F41+H41+I41+K41+M41 | O41: ='⚙ Configurações'!$B$13 | P41: =IF(O41>=1,N41*2,N41/(1-O41)) | Q41: =IF(F41=0,0,ROUND('⚙ Configurações'!$B$23+MAX(0,(0.2-3)*'⚙ Configurações'!$B$29),2)) | R41: =IF(F41=0,0,ROUND('⚙ Configurações'!$B$24+MAX(0,(0.2-3)*'⚙ Configurações'!$B$29),2)) | S41: =IF(F41=0,0,ROUND('⚙ Configurações'!$B$25+MAX(0,(0.2-3)*'⚙ Configurações'!$B$29),2)) | T41: =IF(F41=0,0,ROUND('⚙ Configurações'!$B$26+MAX(0,(0.2-3)*'⚙ Configurações'!$B$29),2)) | U41: =IF(F41=0,0,ROUND('⚙ Configurações'!$B$27+MAX(0,(0.2-3)*'⚙ Configurações'!$B$29),2)) | V41: =IF(F41=0,0,ROUND('⚙ Configurações'!$B$28+MAX(0,(0.2-3)*'⚙ Configurações'!$B$29),2)) | W41: =IF(F41=0,0,ROUND(MAX('⚙ Configurações'!$B$30,P41*'⚙ Configurações'!$B$31),2)) | X41: 0.2 | Y41: =IF(P41=0,0,(P41-N41)/P41) | Z41: 0 | AA41: 0 | AB41: =IF(P41>0,ROUND(P41,2),"")
A42: condutor-de-sementes-para-sensor-agco-acw0551840 | B42: Condutor de Sementes para Sensor — AGCO ACW0551840 | C42: ACW0551840 | D42: AGCO (ADG) | E42: Peças para Plantadeira | F42: 0 | G42: ='⚙ Configurações'!$B$19 | H42: =F42*G42 | I42: =F42*'⚙ Configurações'!$B$20 | J42: ='⚙ Configurações'!$B$4+'⚙ Configurações'!$B$5 | K42: =(F42+H42+I42)*J42 | L42: ='⚙ Configurações'!$B$6+'⚙ Configurações'!$B$7+'⚙ Configurações'!$B$8 | M42: =N42*L42/(1-L42) | N42: =F42+H42+I42+K42+M42 | O42: ='⚙ Configurações'!$B$13 | P42: =IF(O42>=1,N42*2,N42/(1-O42)) | Q42: =IF(F42=0,0,ROUND('⚙ Configurações'!$B$23+MAX(0,(0.2-3)*'⚙ Configurações'!$B$29),2)) | R42: =IF(F42=0,0,ROUND('⚙ Configurações'!$B$24+MAX(0,(0.2-3)*'⚙ Configurações'!$B$29),2)) | S42: =IF(F42=0,0,ROUND('⚙ Configurações'!$B$25+MAX(0,(0.2-3)*'⚙ Configurações'!$B$29),2)) | T42: =IF(F42=0,0,ROUND('⚙ Configurações'!$B$26+MAX(0,(0.2-3)*'⚙ Configurações'!$B$29),2)) | U42: =IF(F42=0,0,ROUND('⚙ Configurações'!$B$27+MAX(0,(0.2-3)*'⚙ Configurações'!$B$29),2)) | V42: =IF(F42=0,0,ROUND('⚙ Configurações'!$B$28+MAX(0,(0.2-3)*'⚙ Configurações'!$B$29),2)) | W42: =IF(F42=0,0,ROUND(MAX('⚙ Configurações'!$B$30,P42*'⚙ Configurações'!$B$31),2)) | X42: 0.2 | Y42: =IF(P42=0,0,(P42-N42)/P42) | Z42: 0 | AA42: 0 | AB42: =IF(P42>0,ROUND(P42,2),"")
A43: condutor-reto-de-sementes-agco-33070004 | B43: Condutor Reto de Sementes — AGCO 33070004 | C43: 33070004 | D43: AGCO (ADG) | E43: Peças para Plantadeira | F43: 0 | G43: ='⚙ Configurações'!$B$19 | H43: =F43*G43 | I43: =F43*'⚙ Configurações'!$B$20 | J43: ='⚙ Configurações'!$B$4+'⚙ Configurações'!$B$5 | K43: =(F43+H43+I43)*J43 | L43: ='⚙ Configurações'!$B$6+'⚙ Configurações'!$B$7+'⚙ Configurações'!$B$8 | M43: =N43*L43/(1-L43) | N43: =F43+H43+I43+K43+M43 | O43: ='⚙ Configurações'!$B$13 | P43: =IF(O43>=1,N43*2,N43/(1-O43)) | Q43: =IF(F43=0,0,ROUND('⚙ Configurações'!$B$23+MAX(0,(0.2-3)*'⚙ Configurações'!$B$29),2)) | R43: =IF(F43=0,0,ROUND('⚙ Configurações'!$B$24+MAX(0,(0.2-3)*'⚙ Configurações'!$B$29),2)) | S43: =IF(F43=0,0,ROUND('⚙ Configurações'!$B$25+MAX(0,(0.2-3)*'⚙ Configurações'!$B$29),2)) | T43: =IF(F43=0,0,ROUND('⚙ Configurações'!$B$26+MAX(0,(0.2-3)*'⚙ Configurações'!$B$29),2)) | U43: =IF(F43=0,0,ROUND('⚙ Configurações'!$B$27+MAX(0,(0.2-3)*'⚙ Configurações'!$B$29),2)) | V43: =IF(F43=0,0,ROUND('⚙ Configurações'!$B$28+MAX(0,(0.2-3)*'⚙ Configurações'!$B$29),2)) | W43: =IF(F43=0,0,ROUND(MAX('⚙ Configurações'!$B$30,P43*'⚙ Configurações'!$B$31),2)) | X43: 0.2 | Y43: =IF(P43=0,0,(P43-N43)/P43) | Z43: 0 | AA43: 0 | AB43: =IF(P43>0,ROUND(P43,2),"")
A44: tampa-maior-do-tubo-agco-acx3473430 | B44: Tampa Maior do Tubo — AGCO ACX3473430 | C44: ACX3473430 | D44: AGCO (ADG) | E44: Peças para Plantadeira | F44: 0 | G44: ='⚙ Configurações'!$B$19 | H44: =F44*G44 | I44: =F44*'⚙ Configurações'!$B$20 | J44: ='⚙ Configurações'!$B$4+'⚙ Configurações'!$B$5 | K44: =(F44+H44+I44)*J44 | L44: ='⚙ Configurações'!$B$6+'⚙ Configurações'!$B$7+'⚙ Configurações'!$B$8 | M44: =N44*L44/(1-L44) | N44: =F44+H44+I44+K44+M44 | O44: ='⚙ Configurações'!$B$13 | P44: =IF(O44>=1,N44*2,N44/(1-O44)) | Q44: =IF(F44=0,0,ROUND('⚙ Configurações'!$B$23+MAX(0,(0.2-3)*'⚙ Configurações'!$B$29),2)) | R44: =IF(F44=0,0,ROUND('⚙ Configurações'!$B$24+MAX(0,(0.2-3)*'⚙ Configurações'!$B$29),2)) | S44: =IF(F44=0,0,ROUND('⚙ Configurações'!$B$25+MAX(0,(0.2-3)*'⚙ Configurações'!$B$29),2)) | T44: =IF(F44=0,0,ROUND('⚙ Configurações'!$B$26+MAX(0,(0.2-3)*'⚙ Configurações'!$B$29),2)) | U44: =IF(F44=0,0,ROUND('⚙ Configurações'!$B$27+MAX(0,(0.2-3)*'⚙ Configurações'!$B$29),2)) | V44: =IF(F44=0,0,ROUND('⚙ Configurações'!$B$28+MAX(0,(0.2-3)*'⚙ Configurações'!$B$29),2)) | W44: =IF(F44=0,0,ROUND(MAX('⚙ Configurações'!$B$30,P44*'⚙ Configurações'!$B$31),2)) | X44: 0.2 | Y44: =IF(P44=0,0,(P44-N44)/P44) | Z44: 0 | AA44: 0 | AB44: =IF(P44>0,ROUND(P44,2),"")
A45: copo-venturi-b-agco-acx363311b-dosador-pneumatico | B45: Copo Venturi B — AGCO ACX363311B | Dosador Pneumático | C45: ACX363311B | D45: AGCO (ADG) | E45: Peças para Plantadeira | F45: 0 | G45: ='⚙ Configurações'!$B$19 | H45: =F45*G45 | I45: =F45*'⚙ Configurações'!$B$20 | J45: ='⚙ Configurações'!$B$4+'⚙ Configurações'!$B$5 | K45: =(F45+H45+I45)*J45 | L45: ='⚙ Configurações'!$B$6+'⚙ Configurações'!$B$7+'⚙ Configurações'!$B$8 | M45: =N45*L45/(1-L45) | N45: =F45+H45+I45+K45+M45 | O45: ='⚙ Configurações'!$B$13 | P45: =IF(O45>=1,N45*2,N45/(1-O45)) | Q45: =IF(F45=0,0,ROUND('⚙ Configurações'!$B$23+MAX(0,(0.2-3)*'⚙ Configurações'!$B$29),2)) | R45: =IF(F45=0,0,ROUND('⚙ Configurações'!$B$24+MAX(0,(0.2-3)*'⚙ Configurações'!$B$29),2)) | S45: =IF(F45=0,0,ROUND('⚙ Configurações'!$B$25+MAX(0,(0.2-3)*'⚙ Configurações'!$B$29),2)) | T45: =IF(F45=0,0,ROUND('⚙ Configurações'!$B$26+MAX(0,(0.2-3)*'⚙ Configurações'!$B$29),2)) | U45: =IF(F45=0,0,ROUND('⚙ Configurações'!$B$27+MAX(0,(0.2-3)*'⚙ Configurações'!$B$29),2)) | V45: =IF(F45=0,0,ROUND('⚙ Configurações'!$B$28+MAX(0,(0.2-3)*'⚙ Configurações'!$B$29),2)) | W45: =IF(F45=0,0,ROUND(MAX('⚙ Configurações'!$B$30,P45*'⚙ Configurações'!$B$31),2)) | X45: 0.2 | Y45: =IF(P45=0,0,(P45-N45)/P45) | Z45: 0 | AA45: 0 | AB45: =IF(P45>0,ROUND(P45,2),"")
A46: copo-venturi-c-agco-acx363311c-dosador-pneumatico | B46: Copo Venturi C — AGCO ACX363311C | Dosador Pneumático | C46: ACX363311C | D46: AGCO (ADG) | E46: Peças para Plantadeira | F46: 0 | G46: ='⚙ Configurações'!$B$19 | H46: =F46*G46 | I46: =F46*'⚙ Configurações'!$B$20 | J46: ='⚙ Configurações'!$B$4+'⚙ Configurações'!$B$5 | K46: =(F46+H46+I46)*J46 | L46: ='⚙ Configurações'!$B$6+'⚙ Configurações'!$B$7+'⚙ Configurações'!$B$8 | M46: =N46*L46/(1-L46) | N46: =F46+H46+I46+K46+M46 | O46: ='⚙ Configurações'!$B$13 | P46: =IF(O46>=1,N46*2,N46/(1-O46)) | Q46: =IF(F46=0,0,ROUND('⚙ Configurações'!$B$23+MAX(0,(0.2-3)*'⚙ Configurações'!$B$29),2)) | R46: =IF(F46=0,0,ROUND('⚙ Configurações'!$B$24+MAX(0,(0.2-3)*'⚙ Configurações'!$B$29),2)) | S46: =IF(F46=0,0,ROUND('⚙ Configurações'!$B$25+MAX(0,(0.2-3)*'⚙ Configurações'!$B$29),2)) | T46: =IF(F46=0,0,ROUND('⚙ Configurações'!$B$26+MAX(0,(0.2-3)*'⚙ Configurações'!$B$29),2)) | U46: =IF(F46=0,0,ROUND('⚙ Configurações'!$B$27+MAX(0,(0.2-3)*'⚙ Configurações'!$B$29),2)) | V46: =IF(F46=0,0,ROUND('⚙ Configurações'!$B$28+MAX(0,(0.2-3)*'⚙ Configurações'!$B$29),2)) | W46: =IF(F46=0,0,ROUND(MAX('⚙ Configurações'!$B$30,P46*'⚙ Configurações'!$B$31),2)) | X46: 0.2 | Y46: =IF(P46=0,0,(P46-N46)/P46) | Z46: 0 | AA46: 0 | AB46: =IF(P46>0,ROUND(P46,2),"")
A47: copo-venturi-agco-acx3601860-dosador-pneumatico | B47: Copo Venturi — AGCO ACX3601860 | Dosador Pneumático | C47: ACX3601860 | D47: AGCO (ADG) | E47: Peças para Plantadeira | F47: 0 | G47: ='⚙ Configurações'!$B$19 | H47: =F47*G47 | I47: =F47*'⚙ Configurações'!$B$20 | J47: ='⚙ Configurações'!$B$4+'⚙ Configurações'!$B$5 | K47: =(F47+H47+I47)*J47 | L47: ='⚙ Configurações'!$B$6+'⚙ Configurações'!$B$7+'⚙ Configurações'!$B$8 | M47: =N47*L47/(1-L47) | N47: =F47+H47+I47+K47+M47 | O47: ='⚙ Configurações'!$B$13 | P47: =IF(O47>=1,N47*2,N47/(1-O47)) | Q47: =IF(F47=0,0,ROUND('⚙ Configurações'!$B$23+MAX(0,(0.2-3)*'⚙ Configurações'!$B$29),2)) | R47: =IF(F47=0,0,ROUND('⚙ Configurações'!$B$24+MAX(0,(0.2-3)*'⚙ Configurações'!$B$29),2)) | S47: =IF(F47=0,0,ROUND('⚙ Configurações'!$B$25+MAX(0,(0.2-3)*'⚙ Configurações'!$B$29),2)) | T47: =IF(F47=0,0,ROUND('⚙ Configurações'!$B$26+MAX(0,(0.2-3)*'⚙ Configurações'!$B$29),2)) | U47: =IF(F47=0,0,ROUND('⚙ Configurações'!$B$27+MAX(0,(0.2-3)*'⚙ Configurações'!$B$29),2)) | V47: =IF(F47=0,0,ROUND('⚙ Configurações'!$B$28+MAX(0,(0.2-3)*'⚙ Configurações'!$B$29),2)) | W47: =IF(F47=0,0,ROUND(MAX('⚙ Configurações'!$B$30,P47*'⚙ Configurações'!$B$31),2)) | X47: 0.2 | Y47: =IF(P47=0,0,(P47-N47)/P47) | Z47: 0 | AA47: 0 | AB47: =IF(P47>0,ROUND(P47,2),"")
A48: vedacao-tubo-de-ar-agco-acx283890a-sistema-pneumatico | B48: Vedação Tubo de Ar — AGCO ACX283890A | Sistema Pneumático | C48: ACX283890A | D48: AGCO (ADG) | E48: Peças para Plantadeira | F48: 0 | G48: ='⚙ Configurações'!$B$19 | H48: =F48*G48 | I48: =F48*'⚙ Configurações'!$B$20 | J48: ='⚙ Configurações'!$B$4+'⚙ Configurações'!$B$5 | K48: =(F48+H48+I48)*J48 | L48: ='⚙ Configurações'!$B$6+'⚙ Configurações'!$B$7+'⚙ Configurações'!$B$8 | M48: =N48*L48/(1-L48) | N48: =F48+H48+I48+K48+M48 | O48: ='⚙ Configurações'!$B$13 | P48: =IF(O48>=1,N48*2,N48/(1-O48)) | Q48: =IF(F48=0,0,ROUND('⚙ Configurações'!$B$23+MAX(0,(0.2-3)*'⚙ Configurações'!$B$29),2)) | R48: =IF(F48=0,0,ROUND('⚙ Configurações'!$B$24+MAX(0,(0.2-3)*'⚙ Configurações'!$B$29),2)) | S48: =IF(F48=0,0,ROUND('⚙ Configurações'!$B$25+MAX(0,(0.2-3)*'⚙ Configurações'!$B$29),2)) | T48: =IF(F48=0,0,ROUND('⚙ Configurações'!$B$26+MAX(0,(0.2-3)*'⚙ Configurações'!$B$29),2)) | U48: =IF(F48=0,0,ROUND('⚙ Configurações'!$B$27+MAX(0,(0.2-3)*'⚙ Configurações'!$B$29),2)) | V48: =IF(F48=0,0,ROUND('⚙ Configurações'!$B$28+MAX(0,(0.2-3)*'⚙ Configurações'!$B$29),2)) | W48: =IF(F48=0,0,ROUND(MAX('⚙ Configurações'!$B$30,P48*'⚙ Configurações'!$B$31),2)) | X48: 0.2 | Y48: =IF(P48=0,0,(P48-N48)/P48) | Z48: 0 | AA48: 0 | AB48: =IF(P48>0,ROUND(P48,2),"")
A49: manipulo-pneumatico-agco-acx310603a | B49: Manípulo Pneumático — AGCO ACX310603A | C49: ACX310603A | D49: AGCO (ADG) | E49: Peças para Plantadeira | F49: 0 | G49: ='⚙ Configurações'!$B$19 | H49: =F49*G49 | I49: =F49*'⚙ Configurações'!$B$20 | J49: ='⚙ Configurações'!$B$4+'⚙ Configurações'!$B$5 | K49: =(F49+H49+I49)*J49 | L49: ='⚙ Configurações'!$B$6+'⚙ Configurações'!$B$7+'⚙ Configurações'!$B$8 | M49: =N49*L49/(1-L49) | N49: =F49+H49+I49+K49+M49 | O49: ='⚙ Configurações'!$B$13 | P49: =IF(O49>=1,N49*2,N49/(1-O49)) | Q49: =IF(F49=0,0,ROUND('⚙ Configurações'!$B$23+MAX(0,(0.2-3)*'⚙ Configurações'!$B$29),2)) | R49: =IF(F49=0,0,ROUND('⚙ Configurações'!$B$24+MAX(0,(0.2-3)*'⚙ Configurações'!$B$29),2)) | S49: =IF(F49=0,0,ROUND('⚙ Configurações'!$B$25+MAX(0,(0.2-3)*'⚙ Configurações'!$B$29),2)) | T49: =IF(F49=0,0,ROUND('⚙ Configurações'!$B$26+MAX(0,(0.2-3)*'⚙ Configurações'!$B$29),2)) | U49: =IF(F49=0,0,ROUND('⚙ Configurações'!$B$27+MAX(0,(0.2-3)*'⚙ Configurações'!$B$29),2)) | V49: =IF(F49=0,0,ROUND('⚙ Configurações'!$B$28+MAX(0,(0.2-3)*'⚙ Configurações'!$B$29),2)) | W49: =IF(F49=0,0,ROUND(MAX('⚙ Configurações'!$B$30,P49*'⚙ Configurações'!$B$31),2)) | X49: 0.2 | Y49: =IF(P49=0,0,(P49-N49)/P49) | Z49: 0 | AA49: 0 | AB49: =IF(P49>0,ROUND(P49,2),"")
A50: conjunto-adaptador-de-vacuo-agco-acx2414460 | B50: Conjunto Adaptador de Vácuo — AGCO ACX2414460 | C50: ACX2414460 | D50: AGCO (ADG) | E50: Peças para Plantadeira | F50: 0 | G50: ='⚙ Configurações'!$B$19 | H50: =F50*G50 | I50: =F50*'⚙ Configurações'!$B$20 | J50: ='⚙ Configurações'!$B$4+'⚙ Configurações'!$B$5 | K50: =(F50+H50+I50)*J50 | L50: ='⚙ Configurações'!$B$6+'⚙ Configurações'!$B$7+'⚙ Configurações'!$B$8 | M50: =N50*L50/(1-L50) | N50: =F50+H50+I50+K50+M50 | O50: ='⚙ Configurações'!$B$13 | P50: =IF(O50>=1,N50*2,N50/(1-O50)) | Q50: =IF(F50=0,0,ROUND('⚙ Configurações'!$B$23+MAX(0,(0.2-3)*'⚙ Configurações'!$B$29),2)) | R50: =IF(F50=0,0,ROUND('⚙ Configurações'!$B$24+MAX(0,(0.2-3)*'⚙ Configurações'!$B$29),2)) | S50: =IF(F50=0,0,ROUND('⚙ Configurações'!$B$25+MAX(0,(0.2-3)*'⚙ Configurações'!$B$29),2)) | T50: =IF(F50=0,0,ROUND('⚙ Configurações'!$B$26+MAX(0,(0.2-3)*'⚙ Configurações'!$B$29),2)) | U50: =IF(F50=0,0,ROUND('⚙ Configurações'!$B$27+MAX(0,(0.2-3)*'⚙ Configurações'!$B$29),2)) | V50: =IF(F50=0,0,ROUND('⚙ Configurações'!$B$28+MAX(0,(0.2-3)*'⚙ Configurações'!$B$29),2)) | W50: =IF(F50=0,0,ROUND(MAX('⚙ Configurações'!$B$30,P50*'⚙ Configurações'!$B$31),2)) | X50: 0.2 | Y50: =IF(P50=0,0,(P50-N50)/P50) | Z50: 0 | AA50: 0 | AB50: =IF(P50>0,ROUND(P50,2),"")
A51: bocal-cotovelo-de-vacuo-agco-acx3371800 | B51: Bocal Cotovelo de Vácuo — AGCO ACX3371800 | C51: ACX3371800 | D51: AGCO (ADG) | E51: Peças para Plantadeira | F51: 0 | G51: ='⚙ Configurações'!$B$19 | H51: =F51*G51 | I51: =F51*'⚙ Configurações'!$B$20 | J51: ='⚙ Configurações'!$B$4+'⚙ Configurações'!$B$5 | K51: =(F51+H51+I51)*J51 | L51: ='⚙ Configurações'!$B$6+'⚙ Configurações'!$B$7+'⚙ Configurações'!$B$8 | M51: =N51*L51/(1-L51) | N51: =F51+H51+I51+K51+M51 | O51: ='⚙ Configurações'!$B$13 | P51: =IF(O51>=1,N51*2,N51/(1-O51)) | Q51: =IF(F51=0,0,ROUND('⚙ Configurações'!$B$23+MAX(0,(0.2-3)*'⚙ Configurações'!$B$29),2)) | R51: =IF(F51=0,0,ROUND('⚙ Configurações'!$B$24+MAX(0,(0.2-3)*'⚙ Configurações'!$B$29),2)) | S51: =IF(F51=0,0,ROUND('⚙ Configurações'!$B$25+MAX(0,(0.2-3)*'⚙ Configurações'!$B$29),2)) | T51: =IF(F51=0,0,ROUND('⚙ Configurações'!$B$26+MAX(0,(0.2-3)*'⚙ Configurações'!$B$29),2)) | U51: =IF(F51=0,0,ROUND('⚙ Configurações'!$B$27+MAX(0,(0.2-3)*'⚙ Configurações'!$B$29),2)) | V51: =IF(F51=0,0,ROUND('⚙ Configurações'!$B$28+MAX(0,(0.2-3)*'⚙ Configurações'!$B$29),2)) | W51: =IF(F51=0,0,ROUND(MAX('⚙ Configurações'!$B$30,P51*'⚙ Configurações'!$B$31),2)) | X51: 0.2 | Y51: =IF(P51=0,0,(P51-N51)/P51) | Z51: 0 | AA51: 0 | AB51: =IF(P51>0,ROUND(P51,2),"")
...

Sheet 🛒 Exportação Shopify
A1: 🛒 EXPORTAÇÃO SHOPIFY — Cole estes dados no Shopify Admin → Products → Import
A2: Copie a coluna 'Variant Price' e cole no campo correspondente do master_products_import.csv para subir preços em lote.
A3: Handle | B3: Título (ref.) | C3: Variant Price (R$) | D3: Variant Compare At Price (R$)
A4: bomba-hidraulica-valtra-valmet-62-65-68-85-86-88-78el-boi-11-e5-p-b4-11-b4-l | B4: Bomba Hidráulica Valtra-Valmet 62/65/68/85/86/88/78EL — Principal | C4: =IF('💰 Formação de Preço'!P4>0,ROUND('💰 Formação de Preço'!P4,2),"") | D4: =IF('💰 Formação de Preço'!AA4>0,ROUND('💰 Formação de Preço'!AA4,2),"")
A5: bomba-hidraulica-valtra-valmet-885-985-1280 | B5: Bomba Hidráulica Principal Valtra-Valmet 885/985/1280 | C5: =IF('💰 Formação de Preço'!P5>0,ROUND('💰 Formação de Preço'!P5,2),"") | D5: =IF('💰 Formação de Preço'!AA5>0,ROUND('💰 Formação de Preço'!AA5,2),"")
A6: bomba-hidraulica-valtra-valmet-880-980-1780 | B6: Bomba Hidráulica Principal Valtra-Valmet 880/980/1780 | C6: =IF('💰 Formação de Preço'!P6>0,ROUND('💰 Formação de Preço'!P6,2),"") | D6: =IF('💰 Formação de Preço'!AA6>0,ROUND('💰 Formação de Preço'!AA6,2),"")
A7: bomba-hidraulica-valtra-valmet-118es-128-138-148 | B7: Bomba Hidráulica Principal Valtra-Valmet 118ES/128/138/148 | C7: =IF('💰 Formação de Preço'!P7>0,ROUND('💰 Formação de Preço'!P7,2),"") | D7: =IF('💰 Formação de Preço'!AA7>0,ROUND('💰 Formação de Preço'!AA7,2),"")
A8: bomba-hidraulica-dupla-valtra-valmet-bh160 | B8: Bomba Hidráulica Dupla Valtra-Valmet BH160 | C8: =IF('💰 Formação de Preço'!P8>0,ROUND('💰 Formação de Preço'!P8,2),"") | D8: =IF('💰 Formação de Preço'!AA8>0,ROUND('💰 Formação de Preço'!AA8,2),"")
A9: bomba-hidraulica-massey-ferguson-mf85x-185-275-285-290-boi-5-5-c10-c10-c6-t10 | B9: Bomba Hidráulica Massey Ferguson MF85X/185/275/285/290 — Direção | C9: =IF('💰 Formação de Preço'!P9>0,ROUND('💰 Formação de Preço'!P9,2),"") | D9: =IF('💰 Formação de Preço'!AA9>0,ROUND('💰 Formação de Preço'!AA9,2),"")
A10: bomba-hidraulica-massey-ferguson-mf290-292-4x2-4x4-boi-7-b11-c11-a15-11-a42-l1 | B10: Bomba Hidráulica Massey Ferguson MF290/292 4x4 — Principal e Direção | C10: =IF('💰 Formação de Preço'!P10>0,ROUND('💰 Formação de Preço'!P10,2),"") | D10: =IF('💰 Formação de Preço'!AA10>0,ROUND('💰 Formação de Preço'!AA10,2),"")
A11: bomba-hidraulica-massey-ferguson-296-4-297-4-299-4-boi-16-b9-p5-a42-19-a42-l1 | B11: Bomba Hidráulica Massey Ferguson 296-4/297-4/299-4 — Principal | C11: =IF('💰 Formação de Preço'!P11>0,ROUND('💰 Formação de Preço'!P11,2),"") | D11: =IF('💰 Formação de Preço'!AA11>0,ROUND('💰 Formação de Preço'!AA11,2),"")
A12: bomba-hidraulica-massey-ferguson-283-290-292-l5000-boi-7-b11-c12-a-11-a-l | B12: Bomba Hidráulica Massey Ferguson 283/290/292/L5000 — Direção e Levante | C12: =IF('💰 Formação de Preço'!P12>0,ROUND('💰 Formação de Preço'!P12,2),"") | D12: =IF('💰 Formação de Preço'!AA12>0,ROUND('💰 Formação de Preço'!AA12,2),"")
A13: bomba-direcao-massey-ferguson-194-4f-362-390 | B13: Bomba de Direção Massey Ferguson 194-4F/362/365/372/390 | C13: =IF('💰 Formação de Preço'!P13>0,ROUND('💰 Formação de Preço'!P13,2),"") | D13: =IF('💰 Formação de Preço'!AA13>0,ROUND('💰 Formação de Preço'!AA13,2),"")
A14: bomba-hidraulica-massey-ferguson-mf-a013 | B14: Bomba Hidráulica Massey Ferguson MF A-013 — Direção e Levante 3000/6000 | C14: =IF('💰 Formação de Preço'!P14>0,ROUND('💰 Formação de Preço'!P14,2),"") | D14: =IF('💰 Formação de Preço'!AA14>0,ROUND('💰 Formação de Preço'!AA14,2),"")
A15: bomba-hidraulica-massey-ferguson-mf-a004-4215-4255 | B15: Bomba Hidráulica Massey Ferguson MF A-004 — 4215/4220/4235/4255 | C15: =IF('💰 Formação de Preço'!P15>0,ROUND('💰 Formação de Preço'!P15,2),"") | D15: =IF('💰 Formação de Preço'!AA15>0,ROUND('💰 Formação de Preço'!AA15,2),"")
... A61: defletor-do-radiador-agco-acx329796a | B61: Defletor do Radiador — AGCO ACX329796A | C61: =IF('💰 Formação de Preço'!P61>0,ROUND('💰 Formação de Preço'!P61,2),"") | D61: =IF('💰 Formação de Preço'!AA61>0,ROUND('💰 Formação de Preço'!AA61,2),"")
A63: 📤 COMO EXPORTAR PARA O SHOPIFY: 1. Abra o arquivo master_products_import.csv em editor de texto ou Excel. 2. Substitua os valores na coluna 'Variant Price' pelos da coluna C desta aba. 3. Importe no Shopify Admin → Products → Import → 'Overwrite existing products'. 4. O campo 'Variant Compare At Price' exibe o preço riscado (pesquisa de mercado máximo).
